Workbook

Sheet Cover
B9: Tesla
B10: Company analysis

Sheet Drivers
B1: Drivers
B3: Selected case | C3: 2
B4: Company | C4: Tesla
B5: Currency | C5: USD
B6: Domestic country | C6: United States
B7: 10-year treasury yield (Sep 18 2020) | C7: 0.00697
B8: Market risk premium US | C8: 0.05
B9: Company beta (Dec 15 2020) | C9: 2.15
B10: Tesla share price (Dec 15 2020) | C10: 639.83
B11: Bond Yield (Sep 18 2020) | C11: 0.04324
B12: Corporate tax rate | C12: 0.21
B13: Expected inflation | C13: 0.02

Sheet Input -->
B14: Input -->

Sheet P&L Input
B1: P&L Input
B3: (in thousands) | C3: 2015 Act | D3: 2016 Act | E3: 2017 Act | F3: 2018 Act | G3: 2019 Act
B4: Automotive revenues | C4: 3740973 | D4: 6350766 | E4: 9641300 | F4: 18514983 | G4: 20821000
B5: Energy generation and storage | C5: 14477 | D5: 181394 | E5: 1116266 | F5: 1555244 | G5: 1531000
B6: Services and other | C6: 290575 | D6: 467972 | E6: 1001185 | F6: 1391041 | G6: 2226000
B7: Total revenues | C7: =SUM(C4:C6) -> 4046025 | D7: =SUM(D4:D6) -> 7000132 | E7: =SUM(E4:E6) -> 11758751 | F7: =SUM(F4:F6) -> 21461268 | G7: =SUM(G4:G6) -> 24578000
B8: Automotive cost of revenues | C8: -2823302 | D8: -4750081 | E8: -7432704 | F8: -14173997 | G8: -16398000
B9: Energy generation and storage cost of revenues | C9: -12287 | D9: -178332 | E9: -874538 | F9: -1364896 | G9: -1341000
B10: Services and other cost of revenues | C10: -286933 | D10: -472462 | E10: -1229022 | F10: -1880354 | G10: -2770000
B11: Gross profit | C11: =SUM(C7:C10) -> 923503 | D11: =SUM(D7:D10) -> 1599257 | E11: =SUM(E7:E10) -> 2222487 | F11: =SUM(F7:F10) -> 4042021 | G11: =SUM(G7:G10) -> 4069000
B12: Research and development | C12: -717900 | D12: -834408 | E12: -1378073 | F12: -1460370 | G12: -1343000
B13: Selling, general and administrative | C13: -922232 | D13: -1432189 | E13: -2476500 | F13: -2834491 | G13: -2646000
B14: Restructuring and other | F14: -135233 | G14: -149000
B15: EBIT | C15: =SUM(C11:C14) -> -716629 | D15: =SUM(D11:D14) -> -667340 | E15: =SUM(E11:E14) -> -1632086 | F15: =SUM(F11:F14) -> -388073 | G15: =SUM(G11:G14) -> -69000
B16: Interest income | C16: 1508 | D16: 8530 | E16: 19686 | F16: 24533 | G16: 44000
B17: Interest expense | C17: -118851 | D17: -198810 | E17: -471259 | F17: -663071 | G17: -685000
B18: Other income (expense), net | C18: -41652 | D18: 111272 | E18: -125373 | F18: 21866 | G18: 45000
B19: EBT | C19: =SUM(C15:C18) -> -875624 | D19: =SUM(D15:D18) -> -746348 | E19: =SUM(E15:E18) -> -2209032 | F19: =SUM(F15:F18) -> -1004745 | G19: =SUM(G15:G18) -> -665000
B20: Provision for income taxes | C20: -13039 | D20: -26698 | E20: -31546 | F20: -57837 | G20: -110000
B21: Net loss incl. minority interests | C21: =SUM(C19:C20) -> -888663 | D21: =SUM(D19:D20) -> -773046 | E21: =SUM(E19:E20) -> -2240578 | F21: =SUM(F19:F20) -> -1062582 | G21: =SUM(G19:G20) -> -775000
B22: Minority interests | C22: 0 | D22: 98132 | E22: 279178 | F22: 86491 | G22: -87000
B23: Net loss | C23: =SUM(C21:C22) -> -888663 | D23: =SUM(D21:D22) -> -674914 | E23: =SUM(E21:E22) -> -1961400 | F23: =SUM(F21:F22) -> -976091 | G23: =SUM(G21:G22) -> -862000
B25: KPIs
B26: Revenue % automotive y-o-y | D26: =D4/C4-1 -> 0.69762412 | E26: =E4/D4-1 -> 0.51813183 | F26: =F4/E4-1 -> 0.92038242 | G26: =G4/F4-1 -> 0.1245487
B27: Revenue % generation y-o-y | D27: =D5/C5-1 -> 11.529806 | E27: =E5/D5-1 -> 5.1538199 | F27: =F5/E5-1 -> 0.39325573 | G27: =G5/F5-1 -> -0.015588551
B28: Revenue % services y-o-y | D28: =D6/C6-1 -> 0.61050331 | E28: =E6/D6-1 -> 1.1394122 | F28: =F6/E6-1 -> 0.38939457 | G28: =G6/F6-1 -> 0.6002404
B29: GP% automotive | C29: =(C4+C8)/C4 -> 0.24530276 | D29: =(D4+D8)/D4 -> 0.25204597 | E29: =(E4+E8)/E4 -> 0.22907658 | F29: =(F4+F8)/F4 -> 0.23445801 | G29: =(G4+G8)/G4 -> 0.21242976
B30: GP% energy generation and automotive | C30: =(C5+C9)/C5 -> 0.15127444 | D30: =(D5+D9)/D5 -> 0.016880382 | E30: =(E5+E9)/E5 -> 0.21655054 | F30: =(F5+F9)/F5 -> 0.12239108 | G30: =(G5+G9)/G5 -> 0.12410189
B31: GP% services and other | C31: =(C6+C10)/C6 -> 0.012533769 | D31: =(D6+D10)/D6 -> -0.0095945911 | E31: =(E6+E10)/E6 -> -0.22756733 | F31: =(F6+F10)/F6 -> -0.3517603 | G31: =(G6+G10)/G6 -> -0.24438455
B32: Overall GP% | C32: =(SUM(C4:C6)+SUM(C8:C10))/SUM(C4:C6) -> 0.22824945 | D32: =(SUM(D4:D6)+SUM(D8:D10))/SUM(D4:D6) -> 0.22846098 | E32: =(SUM(E4:E6)+SUM(E8:E10))/SUM(E4:E6) -> 0.18900706 | F32: =(SUM(F4:F6)+SUM(F8:F10))/SUM(F4:F6) -> 0.18834027 | G32: =(SUM(G4:G6)+SUM(G8:G10))/SUM(G4:G6) -> 0.16555456
B33: EBIT % | C33: =C15/C7 -> -0.17711927 | D33: =D15/D7 -> -0.095332488 | E33: =E15/E7 -> -0.13879756 | F33: =F15/F7 -> -0.018082482 | G33: =G15/G7 -> -0.0028073887
B34: Net loss % | C34: =C23/C7 -> -0.21963853 | D34: =D23/D7 -> -0.096414468 | E34: =E23/E7 -> -0.16680343 | F34: =F23/F7 -> -0.045481516 | G34: =G23/G7 -> -0.035072016
B35: ROA | C35: =C23/'Balance Sheet Input'!C18 -> -0.11014746 | D35: =D23/'Balance Sheet Input'!D18 -> -0.029779021 | E35: =E23/'Balance Sheet Input'!E18 -> -0.068447899 | F35: =F23/'Balance Sheet Input'!F18 -> -0.03282124 | G35: =G23/'Balance Sheet Input'!G18 -> -0.025124603
B36: ROE | C36: =C23/'Balance Sheet Input'!C32 -> -0.82002373 | D36: =D23/'Balance Sheet Input'!D32 -> -0.14200013 | E36: =E23/'Balance Sheet Input'!E32 -> -0.46289544 | F36: =F23/'Balance Sheet Input'!F32 -> -0.1982618 | G36: =G23/'Balance Sheet Input'!G32 -> -0.13025083

Sheet Balance Sheet Input
B1: Balance Sheet Input
B3: (in thousands) | C3: 31 Dec 2015 | D3: 31 Dec 2016 | E3: 31 Dec 2017 | F3: 31 Dec 2018 | G3: 31 Dec 2019
B4: Cash and cash equivalents | C4: 1196908 | D4: 3393216 | E4: 3367914 | F4: 3685618 | G4: 6268000
B5: Restricted cash and marketable securities | C5: 22628 | D5: 105519 | E5: 155323 | F5: 192551 | G5: 246000
B6: Accounts receivable, net | C6: 168965 | D6: 499142 | E6: 515381 | F6: 949022 | G6: 1324000
B7: Inventory | C7: 1277838 | D7: 2067454 | E7: 2263537 | F7: 3113446 | G7: 3552000
B8: Prepaid expenses and other current assets | C8: 115667 | D8: 194465 | E8: 268365 | F8: 365671 | G8: 713000
B9: Total current assets | C9: =SUM(C4:C8) -> 2782006 | D9: =SUM(D4:D8) -> 6259796 | E9: =SUM(E4:E8) -> 6570520 | F9: =SUM(F4:F8) -> 8306308 | G9: =SUM(G4:G8) -> 12103000
B10: Operating lease vehicles, net | C10: 1791403 | D10: 3134080 | E10: 4116604 | F10: 2089758 | G10: 2447000
B11: Solar energy systems, leased and to be leased, net | C11: 0 | D11: 5919880 | E11: 6347490 | F11: 6271396 | G11: 6138000
B12: Property, plant and equipment, net | C12: 3403334 | D12: 5982957 | E12: 10027522 | F12: 11330077 | G12: 10396000
B13: Operating lease right-of-use assets | C13: 0 | D13: 0 | E13: 0 | F13: 0 | G13: 1218000
B14: Intangible assets, net | C14: 12816 | D14: 376145 | E14: 361502 | F14: 282492 | G14: 339000
B15: portion | C15: 0 | D15: 506302 | E15: =456652+60237 -> 516889 | F15: 489707 | G15: 591000
B16: Restricted cash, net of current portion | C16: 31522 | D16: 268165 | E16: 441722 | F16: 398219 | G16: 269000
B17: Other assets | C17: 46858 | D17: 216751 | E17: 273123 | F17: 571657 | G17: 808000
B18: Total assets | C18: =SUM(C9:C17) -> 8067939 | D18: =SUM(D9:D17) -> 22664076 | E18: =SUM(E9:E17) -> 28655372 | F18: =SUM(F9:F17) -> 29739614 | G18: =SUM(G9:G17) -> 34309000
B19: Accounts payable | C19: 916148 | D19: 1860341 | E19: 2390250 | F19: 3404451 | G19: 3771000
B20: Accrued liabilities | C20: 422798 | D20: 1210028 | E20: 1731366 | F20: 2094253 | G20: 2905000
B21: Deferred revenue | C21: 423961 | D21: 763126 | E21: 1015253 | F21: 630292 | G21: 1163000
B22: Resale value guarantees | C22: 136831 | D22: 179504 | E22: 787333 | F22: 502840 | G22: 317000
B23: Customer deposits | C23: 283370 | D23: 663859 | E23: 853919 | F23: 792601 | G23: 726000
B24: Current portion of long-term debt and capital leases | C24: 627927 | D24: 984211 | E24: 796549 | F24: 2567699 | G24: 1785000
B25: Current portion of solar bonds issued to related
B26: parties | C26: 0 | D26: 165936 | E26: 100000 | F26: 0 | G26: 0
B27: Total current liabilities | C27: 2811035 | D27: 5827005 | E27: =SUM(E19:E26) -> 7674670 | F27: =SUM(F19:F26) -> 9992136 | G27: =SUM(G19:G26) -> 10667000
B28: Long-term debt and capital leases, net of current
B29: portion | C29: 2021093 | D29: 5860049 | E29: 9415700 | F29: 9403672 | G29: 11634000
B30: Other liabilities | C30: 2152107 | D30: 5438936 | E30: 6330414 | F30: 4586166 | G30: 4541000
B31: Total liabilities | C31: =SUM(C27:C30) -> 6984235 | D31: =SUM(D27:D30) -> 17125990 | E31: =SUM(E27:E30) -> 23420784 | F31: =SUM(F27:F30) -> 23981974 | G31: =SUM(G27:G30) -> 26842000
B32: Total stockholders' equity | C32: 1083704 | D32: 4752911 | E32: 4237242 | F32: 4923243 | G32: 6618000
B33: Noncontrolling interests in subsidiaries | C33: 0 | D33: 785175 | E33: 997346 | F33: 834397 | G33: 849000
B34: Total liabilities and equity | C34: =C31+C32+C33 -> 8067939 | D34: =D31+D32+D33 -> 22664076 | E34: =E31+E32+E33 -> 28655372 | F34: =F31+F32+F33 -> 29739614 | G34: =G31+G32+G33 -> 34309000
B36: KPIs
B37: Liquidity ratios
B38: Quick ratio | C38: =(C4+C5)/C27 -> 0.43383878 | D38: =(D4+D5)/D27 -> 0.60043453 | E38: =(E4+E5)/E27 -> 0.45907342 | F38: =(F4+F5)/F27 -> 0.38812212 | G38: =(G4+G5)/G27 -> 0.61066842
B39: Current ratio | C39: =C9/C27 -> 0.9896732 | D39: =D9/D27 -> 1.0742733 | E39: =E9/E27 -> 0.85613062 | F39: =F9/F27 -> 0.83128452 | G39: =G9/G27 -> 1.1346208
B40: DSO | C40: =C6/'P&L Input'!C7*360 -> 15.033867 | D40: =D6/'P&L Input'!D7*360 -> 25.669676 | E40: =E6/'P&L Input'!E7*360 -> 15.778645 | F40: =F6/'P&L Input'!F7*360 -> 15.919279 | G40: =G6/'P&L Input'!G7*360 -> 19.392953
B41: DIO | C41: =-C7/SUM('P&L Input'!C8:C10)*360 -> 147.32376 | D41: =-D7/SUM('P&L Input'!D8:D10)*360 -> 137.80794 | E41: =-E7/SUM('P&L Input'!E8:E10)*360 -> 85.449954 | F41: =-F7/SUM('P&L Input'!F8:F10)*360 -> 64.344949 | G41: =-G7/SUM('P&L Input'!G8:G10)*360 -> 62.349213
B42: DPO | C42: =-C19/SUM('P&L Input'!C8:C10)*360 -> 105.62401 | D42: =-D19/SUM('P&L Input'!D8:D10)*360 -> 124.00264 | E42: =-E19/SUM('P&L Input'!E8:E10)*360 -> 90.23345 | F42: =-F19/SUM('P&L Input'!F8:F10)*360 -> 70.35909 | G42: =-G19/SUM('P&L Input'!G8:G10)*360 -> 66.193379
...

Sheet Workings -->
B14: Workings -->

Sheet Income Statement items
B14: Income Statement items

Sheet Automotive
B14: Automotive

Sheet Deliveries
B1: Deliveries
C3: Tesla Deliveries
B4: Vehicle | C4: 2015 Act | D4: 2016 Act | E4: 2017 Act | F4: 2018 Act | G4: 2019 Act | H4: 2020 Fcst | I4: 2021 Fcst | J4: 2022 Fcst | K4: 2023 Fcst | L4: 2024 Fcst | M4: 2025 Fcst | N4: 2026 Fcst | O4: 2027 Fcst | P4: 2028 Fcst | Q4: 2029 Fcst
B5: Tesla Model 3 | C5: 0 | D5: 0 | E5: 1764 | F5: 146055 | G5: 300815 | H5: =G5*(1+H15) -> 481304 | I5: =H5*(1+I15) -> 529434.4 | J5: =I5*(1+J15) -> 582377.84 | K5: =J5*(1+K15) -> 628968.07 | L5: =K5*(1+L15) -> 679285.51 | M5: =L5*(1+M15) -> 706456.93 | N5: =M5*(1+N15) -> 734715.21 | O5: =N5*(1+O15) -> 764103.82 | ... Q5: =P5*(1+Q15) -> 826454.69
B6: Tesla Model S and X | C6: 50580 | D6: 76230 | E6: 101312 | F6: 98865 | G6: 66385 | H6: =G6*(1+H16) -> 69040.4 | I6: =H6*(1+I16) -> 71802.016 | J6: =I6*(1+J16) -> 74674.097 | K6: =J6*(1+K16) -> 77661.061 | L6: =K6*(1+L16) -> 80767.503 | M6: =L6*(1+M16) -> 83998.203 | N6: =M6*(1+N16) -> 87358.131 | O6: =N6*(1+O16) -> 90852.456 | ... Q6: =P6*(1+Q16) -> 98266.017
B7: Tesla Model Y | C7: 0 | D7: 0 | E7: 0 | F7: 0 | G7: 0 | H7: =E5 -> 1764 | I7: =H7*(1+I17) -> 146055 | J7: =I7*(1+J17) -> 300815 | K7: =J7*(1+K17) -> 481304 | L7: =K7*(1+L17) -> 529434.4 | M7: =L7*(1+M17) -> 582377.84 | N7: =M7*(1+N17) -> 628968.07 | O7: =N7*(1+O17) -> 679285.51 | P7: =O7*(1+P17) -> 706456.93 | Q7: =P7*(1+Q17) -> 734715.21
B8: Tesla Roadster 2 | C8: 0 | D8: 0 | E8: 0 | F8: 0 | G8: 0 | H8: 0 | I8: 0 | J8: 500 | K8: =J8*(1+K18) -> 1000 | L8: =K8*(1+L18) -> 1500 | M8: =L8*(1+M18) -> 1650 | N8: =M8*(1+N18) -> 1815 | O8: =N8*(1+O18) -> 1960.2 | P8: =O8*(1+P18) -> 2117.016 | Q8: =P8*(1+Q18) -> 2201.6966
B9: Tesla Pickup | C9: 0 | D9: 0 | E9: 0 | F9: 0 | G9: 0 | H9: 0 | I9: 250 | J9: =I9*(1+J19) -> 20699.405 | K9: =J9*(1+K19) -> 42632.511 | L9: =K9*(1+L19) -> 68212.018 | M9: =L9*(1+M19) -> 75033.22 | N9: =M9*(1+N19) -> 82536.542 | O9: =N9*(1+O19) -> 89139.465 | P9: =O9*(1+P19) -> 96270.623 | Q9: =P9*(1+Q19) -> 100121.45
B10: Tesla Semi | C10: 0 | D10: 0 | E10: 0 | F10: 0 | G10: 0 | H10: 0 | I10: 250 | J10: =I10*(1+J20) -> 20699.405 | K10: =J10*(1+K20) -> 42632.511 | L10: =K10*(1+L20) -> 68212.018 | M10: =L10*(1+M20) -> 75033.22 | N10: =M10*(1+N20) -> 82536.542 | O10: =N10*(1+O20) -> 89139.465 | P10: =O10*(1+P20) -> 96270.623 | Q10: =P10*(1+Q20) -> 100121.45
B11: Total | C11: =SUM(C5:C10) -> 50580 | D11: =SUM(D5:D10) -> 76230 | E11: =SUM(E5:E10) -> 103076 | F11: =SUM(F5:F10) -> 244920 | G11: =SUM(G5:G10) -> 367200 | H11: =SUM(H5:H10) -> 552108.4 | I11: =SUM(I5:I10) -> 747791.42 | J11: =SUM(J5:J10) -> 999765.75 | ... Q11: =SUM(Q5:Q10) -> 1861880.5
B13: y-o-y growth %
B15: Tesla Model 3 | C15: n.a. | D15: n.a. | E15: n.a. | F15: =F5/E5-1 -> 81.797619 | G15: =G5/F5-1 -> 1.0596008 | H15: 0.6 | I15: =$C$25 -> 0.1 | J15: =$C$25 -> 0.1 | K15: =$C$26 -> 0.08 | L15: =$C$26 -> 0.08 | M15: =$C$27 -> 0.04 | N15: =$C$27 -> 0.04 | O15: =$C$27 -> 0.04 | P15: =$C$27 -> 0.04 | Q15: =$C$27 -> 0.04
B16: Tesla Model S and X | C16: n.a. | D16: =D6/C6-1 -> 0.50711744 | E16: =E6/D6-1 -> 0.32903057 | F16: =F6/E6-1 -> -0.024153111 | G16: =G6/F6-1 -> -0.3285288 | H16: =$C$27 -> 0.04 | I16: =$C$27 -> 0.04 | J16: =$C$27 -> 0.04 | K16: =$C$27 -> 0.04 | L16: =$C$27 -> 0.04 | M16: =$C$27 -> 0.04 | N16: =$C$27 -> 0.04 | O16: =$C$27 -> 0.04 | ... Q16: =$C$27 -> 0.04
B17: Tesla Model Y | C17: n.a. | D17: n.a. | E17: n.a. | F17: n.a. | G17: n.a. | H17: n.a. | I17: =F15 -> 81.797619 | J17: =G15 -> 1.0596008 | K17: =H15 -> 0.6 | L17: =I15 -> 0.1 | M17: =J15 -> 0.1 | N17: =K15 -> 0.08 | O17: =L15 -> 0.08 | P17: =M15 -> 0.04 | Q17: =N15 -> 0.04
B18: Tesla Roadster 2 | C18: n.a. | D18: n.a. | E18: n.a. | F18: n.a. | G18: n.a. | H18: n.a. | I18: n.a. | J18: n.a. | K18: 1 | L18: 0.5 | M18: =$C$25 -> 0.1 | N18: =$C$25 -> 0.1 | O18: =$C$26 -> 0.08 | P18: =$C$26 -> 0.08 | Q18: =$C$27 -> 0.04
B19: Tesla Pickup | C19: n.a. | D19: n.a. | E19: n.a. | F19: n.a. | G19: n.a. | H19: n.a. | I19: n.a. | J19: =F$15 -> 81.797619 | K19: =G$15 -> 1.0596008 | L19: =H$15 -> 0.6 | M19: =$C$25 -> 0.1 | N19: =$C$25 -> 0.1 | O19: =$C$26 -> 0.08 | P19: =$C$26 -> 0.08 | Q19: =$C$27 -> 0.04
B20: Tesla Semi | C20: n.a. | D20: n.a. | E20: n.a. | F20: n.a. | G20: n.a. | H20: n.a. | I20: n.a. | J20: =F$15 -> 81.797619 | K20: =G$15 -> 1.0596008 | L20: =H$15 -> 0.6 | M20: =$C$25 -> 0.1 | N20: =$C$25 -> 0.1 | O20: =$C$26 -> 0.08 | P20: =$C$26 -> 0.08 | Q20: =$C$27 -> 0.04
B24: Assumed growth after introduction:
B25: 2 years | C25: 0.1
B26: 2 years | C26: 0.08
B27: onwards | C27: 0.04

Sheet Deliveries development

Sheet Deliveries comparables
B1: Deliveries comparables
B3: Comparables 2015-2019
B6: Vehicle Sales 2015-2019 - average | C6: Average | D6: Adj. Average
B7: GM | C7: 9600340 | D7: =C7 -> 9600340
B8: Ford | C8: 6607000 | D8: =C8 -> 6607000
B9: Fiat Chrysler | C9: 4740000 | D9: =C9 -> 4740000
B10: BMW | C10: 2460000 | D10: =C10 -> 2460000
B11: Volkswagen | C11: 10700000 | D11: =C11 -> 10700000
B12: Jaguar | C12: n.a. | D12: n.a.
B13: Porsche | C13: n.a. | D13: n.a.
B14: Ferrari | C14: n.a. | D14: n.a.
B15: Scania | C15: n.a. | D15: n.a.
B16: MAN | C16: n.a. | D16: n.a.
B17: Paccar | C17: n.a. | D17: n.a.
B18: Average | C18: n.a. | D18: =AVERAGE(D7:D17) -> 6821468
B22: Tesla Expected Deliveries
B23: 2020 | D23: =Deliveries!H$11 -> 552108.4
B24: 2024 | D24: =Deliveries!L$11 -> 1427411.5
B25: 2029 | D25: =Deliveries!Q$11 -> 1861880.5

Sheet Average Prices
B1: Average prices
B3: Model and Version | C3: Range | D3: Base price | E3: Fully loaded | F3: Average Price per Model
B4: Model 3 Standard Range Plus | C4: 250 miles | D4: 39990 | E4: 51490
B5: Model 3 Long Range | C5: 322 miles | D5: 48990 | E5: 60490
B6: Model 3 Performance | C6: 322 miles | D6: 56990 | E6: 66990
B7: Average Model 3 | F7: =AVERAGE(D4:E6) -> 54156.667
B8: Model S Long Range | C8: 373 miles | D8: 79990 | E8: 95490
B9: Model S Performance | C9: 348 miles | D9: 99990 | E9: 115990
B10: Model X Long Range | C10: 328 miles | D10: 84990 | E10: 106490
B11: Model X Performance | C11: 305 miles | D11: 104990 | E11: 128490
B12: Average Model S and X | F12: =AVERAGE(D8:E11) -> 102052.5
B14: Model | C14: Base price | D14: Max price
B15: CyberTruck | C15: 39900 | D15: 76900 | F15: =AVERAGE(C15:D15) -> 58400
B16: Model Y | C16: 48000 | D16: 74000 | F16: =AVERAGE(C16:D16) -> 61000
B17: Roadster 2020 | C17: 200000 | D17: 250000 | F17: =AVERAGE(C17:D17) -> 225000
B18: Semi | C18: 150000 | D18: 200000 | F18: =AVERAGE(C18:D18) -> 175000

Sheet Revenue automotive
B1: Revenue Automotive
C3: Tesla Revenue Automotive (in mln $)
B4: Vehicle | C4: 2015 Act | D4: 2016 Act | E4: 2017 Act | F4: 2018 Act | G4: 2019 Act | H4: 2020 Fcst | I4: 2021 Fcst | J4: 2022 Fcst | K4: 2023 Fcst | L4: 2024 Fcst | M4: 2025 Fcst | N4: 2026 Fcst | O4: 2027 Fcst | P4: 2028 Fcst | Q4: 2029 Fcst | R4: Average Price ($)
B5: Tesla Model 3 | E5: 88.268789 | F5: 8136.483 | G5: 14705.599 | H5: =($R5*Deliveries!H5)*H14/1000000 -> 26065.82 | I5: =($R5*Deliveries!I5)*I14/1000000 -> 28672.402 | J5: =($R5*Deliveries!J5)*J14/1000000 -> 31539.643 | K5: =($R5*Deliveries!K5)*K14/1000000 -> 34062.814 | L5: =($R5*Deliveries!L5)*L14/1000000 -> 36787.839 | M5: =($R5*Deliveries!M5)*M14/1000000 -> 38259.353 | N5: =($R5*Deliveries!N5)*N14/1000000 -> 39789.727 | O5: =($R5*Deliveries!O5)*O14/1000000 -> 41381.316 | ... Q5: =($R5*Deliveries!Q5)*Q14/1000000 -> 44758.031 | R5: =AVERAGE('Average Prices'!D4:E6) -> 54156.667
B6: Tesla Model S and X | C6: 3740.973 | D6: 6350.766 | E6: 9553.0312 | F6: 10378.5 | G6: 6115.4007 | H6: =($R6*Deliveries!H6)*H15/1000000 -> 7045.7454 | I6: =($R6*Deliveries!I6)*I15/1000000 -> 7327.5752 | J6: =($R6*Deliveries!J6)*J15/1000000 -> 7620.6782 | K6: =($R6*Deliveries!K6)*K15/1000000 -> 7925.5054 | L6: =($R6*Deliveries!L6)*L15/1000000 -> 8242.5256 | M6: =($R6*Deliveries!M6)*M15/1000000 -> 8572.2266 | N6: =($R6*Deliveries!N6)*N15/1000000 -> 8915.1157 | O6: =($R6*Deliveries!O6)*O15/1000000 -> 9271.7203 | ... Q6: =($R6*Deliveries!Q6)*Q15/1000000 -> 10028.293 | R6: =AVERAGE('Average Prices'!D8:E11) -> 102052.5
B7: Tesla Model Y | C7: =($R7*Deliveries!C7)/1000000 -> 0 | D7: =($R7*Deliveries!D7)/1000000 -> 0 | E7: =($R7*Deliveries!E7)/1000000 -> 0 | F7: =($R7*Deliveries!F7)/1000000 -> 0 | G7: =($R7*Deliveries!G7)/1000000 -> 0 | H7: =($R7*Deliveries!H7)*H16/1000000 -> 107.604 | I7: =($R7*Deliveries!I7)*I16/1000000 -> 8909.355 | J7: =($R7*Deliveries!J7)*J16/1000000 -> 18349.715 | K7: =($R7*Deliveries!K7)*K16/1000000 -> 29359.544 | L7: =($R7*Deliveries!L7)*L16/1000000 -> 32295.498 | M7: =($R7*Deliveries!M7)*M16/1000000 -> 35525.048 | N7: =($R7*Deliveries!N7)*N16/1000000 -> 38367.052 | O7: =($R7*Deliveries!O7)*O16/1000000 -> 41436.416 | ... Q7: =($R7*Deliveries!Q7)*Q16/1000000 -> 44817.628 | R7: =AVERAGE('Average Prices'!C16:D16) -> 61000
B8: Tesla Roadster 2 | C8: =($R8*Deliveries!C8)/1000000 -> 0 | D8: =($R8*Deliveries!D8)/1000000 -> 0 | E8: =($R8*Deliveries!E8)/1000000 -> 0 | F8: =($R8*Deliveries!F8)/1000000 -> 0 | G8: =($R8*Deliveries!G8)/1000000 -> 0 | H8: =($R8*Deliveries!H8)*H17/1000000 -> 0 | I8: =($R8*Deliveries!I8)*I17/1000000 -> 0 | J8: =($R8*Deliveries!J8)*J17/1000000 -> 112.5 | K8: =($R8*Deliveries!K8)*K17/1000000 -> 225 | L8: =($R8*Deliveries!L8)*L17/1000000 -> 337.5 | M8: =($R8*Deliveries!M8)*M17/1000000 -> 371.25 | N8: =($R8*Deliveries!N8)*N17/1000000 -> 408.375 | O8: =($R8*Deliveries!O8)*O17/1000000 -> 441.045 | ... Q8: =($R8*Deliveries!Q8)*Q17/1000000 -> 495.38174 | R8: =AVERAGE('Average Prices'!C17:D17) -> 225000
B9: Tesla Pickup | C9: =($R9*Deliveries!C9)/1000000 -> 0 | D9: =($R9*Deliveries!D9)/1000000 -> 0 | E9: =($R9*Deliveries!E9)/1000000 -> 0 | F9: =($R9*Deliveries!F9)/1000000 -> 0 | G9: =($R9*Deliveries!G9)/1000000 -> 0 | H9: =($R9*Deliveries!H9)*H18/1000000 -> 0 | I9: =($R9*Deliveries!I9)*I18/1000000 -> 14.6 | J9: =($R9*Deliveries!J9)*J18/1000000 -> 1208.8452 | K9: =($R9*Deliveries!K9)*K18/1000000 -> 2489.7387 | L9: =($R9*Deliveries!L9)*L18/1000000 -> 3983.5819 | M9: =($R9*Deliveries!M9)*M18/1000000 -> 4381.94 | N9: =($R9*Deliveries!N9)*N18/1000000 -> 4820.134 | O9: =($R9*Deliveries!O9)*O18/1000000 -> 5205.7448 | ... Q9: =($R9*Deliveries!Q9)*Q18/1000000 -> 5847.0925 | R9: =AVERAGE('Average Prices'!C15:D15) -> 58400
B10: Tesla Semi | C10: =($R10*Deliveries!C10)/1000000 -> 0 | D10: =($R10*Deliveries!D10)/1000000 -> 0 | E10: =($R10*Deliveries!E10)/1000000 -> 0 | F10: =($R10*Deliveries!F10)/1000000 -> 0 | G10: =($R10*Deliveries!G10)/1000000 -> 0 | H10: =($R10*Deliveries!H10)*H19/1000000 -> 0 | I10: =($R10*Deliveries!I10)*I19/1000000 -> 43.75 | J10: =($R10*Deliveries!J10)*J19/1000000 -> 3622.3958 | K10: =($R10*Deliveries!K10)*K19/1000000 -> 7460.6895 | L10: =($R10*Deliveries!L10)*L19/1000000 -> 11937.103 | M10: =($R10*Deliveries!M10)*M19/1000000 -> 13130.813 | N10: =($R10*Deliveries!N10)*N19/1000000 -> 14443.895 | O10: =($R10*Deliveries!O10)*O19/1000000 -> 15599.406 | ... Q10: =($R10*Deliveries!Q10)*Q19/1000000 -> 17521.253 | R10: =AVERAGE('Average Prices'!C18:D18) -> 175000
B11: Total | C11: =SUM(C5:C10) -> 3740.973 | D11: =SUM(D5:D10) -> 6350.766 | E11: =SUM(E5:E10) -> 9641.3 | F11: ='P&L Input'!F4/1000 -> 18514.983 | G11: ='P&L Input'!G4/1000 -> 20821 | H11: =SUM(H5:H10) -> 33219.17 | I11: =SUM(I5:I10) -> 44967.683 | J11: =SUM(J5:J10) -> 62453.777 | K11: =SUM(K5:K10) -> 81523.291 | L11: =SUM(L5:L10) -> 93584.048 | M11: =SUM(M5:M10) -> 100240.63 | N11: =SUM(N5:N10) -> 106744.3 | O11: =SUM(O5:O10) -> 113335.65 | ... Q11: =SUM(Q5:Q10) -> 123467.68
B13: Selected case
B14: Tesla Model 3 | H14: =CHOOSE(Drivers!$C$3,'Revenue automotive'!H22,'Revenue automotive'!H30,'Revenue automotive'!H38) -> 1 | I14: =CHOOSE(Drivers!$C$3,'Revenue automotive'!I22,'Revenue automotive'!I30,'Revenue automotive'!I38) -> 1 | J14: =CHOOSE(Drivers!$C$3,'Revenue automotive'!J22,'Revenue automotive'!J30,'Revenue automotive'!J38) -> 1 | K14: =CHOOSE(Drivers!$C$3,'Revenue automotive'!K22,'Revenue automotive'!K30,'Revenue automotive'!K38) -> 1 | L14: =CHOOSE(Drivers!$C$3,'Revenue automotive'!L22,'Revenue automotive'!L30,'Revenue automotive'!L38) -> 1 | M14: =CHOOSE(Drivers!$C$3,'Revenue automotive'!M22,'Revenue automotive'!M30,'Revenue automotive'!M38) -> 1 | N14: =CHOOSE(Drivers!$C$3,'Revenue automotive'!N22,'Revenue automotive'!N30,'Revenue automotive'!N38) -> 1 | O14: =CHOOSE(Drivers!$C$3,'Revenue automotive'!O22,'Revenue automotive'!O30,'Revenue automotive'!O38) -> 1 | ... Q14: =CHOOSE(Drivers!$C$3,'Revenue automotive'!Q22,'Revenue automotive'!Q30,'Revenue automotive'!Q38) -> 1
B15: Tesla Model S and X | H15: =CHOOSE(Drivers!$C$3,'Revenue automotive'!H23,'Revenue automotive'!H31,'Revenue automotive'!H39) -> 1 | I15: =CHOOSE(Drivers!$C$3,'Revenue automotive'!I23,'Revenue automotive'!I31,'Revenue automotive'!I39) -> 1 | J15: =CHOOSE(Drivers!$C$3,'Revenue automotive'!J23,'Revenue automotive'!J31,'Revenue automotive'!J39) -> 1 | K15: =CHOOSE(Drivers!$C$3,'Revenue automotive'!K23,'Revenue automotive'!K31,'Revenue automotive'!K39) -> 1 | L15: =CHOOSE(Drivers!$C$3,'Revenue automotive'!L23,'Revenue automotive'!L31,'Revenue automotive'!L39) -> 1 | M15: =CHOOSE(Drivers!$C$3,'Revenue automotive'!M23,'Revenue automotive'!M31,'Revenue automotive'!M39) -> 1 | N15: =CHOOSE(Drivers!$C$3,'Revenue automotive'!N23,'Revenue automotive'!N31,'Revenue automotive'!N39) -> 1 | O15: =CHOOSE(Drivers!$C$3,'Revenue automotive'!O23,'Revenue automotive'!O31,'Revenue automotive'!O39) -> 1 | ... Q15: =CHOOSE(Drivers!$C$3,'Revenue automotive'!Q23,'Revenue automotive'!Q31,'Revenue automotive'!Q39) -> 1
B16: Tesla Model Y | H16: =CHOOSE(Drivers!$C$3,'Revenue automotive'!H24,'Revenue automotive'!H32,'Revenue automotive'!H40) -> 1 | I16: =CHOOSE(Drivers!$C$3,'Revenue automotive'!I24,'Revenue automotive'!I32,'Revenue automotive'!I40) -> 1 | J16: =CHOOSE(Drivers!$C$3,'Revenue automotive'!J24,'Revenue automotive'!J32,'Revenue automotive'!J40) -> 1 | K16: =CHOOSE(Drivers!$C$3,'Revenue automotive'!K24,'Revenue automotive'!K32,'Revenue automotive'!K40) -> 1 | L16: =CHOOSE(Drivers!$C$3,'Revenue automotive'!L24,'Revenue automotive'!L32,'Revenue automotive'!L40) -> 1 | M16: =CHOOSE(Drivers!$C$3,'Revenue automotive'!M24,'Revenue automotive'!M32,'Revenue automotive'!M40) -> 1 | N16: =CHOOSE(Drivers!$C$3,'Revenue automotive'!N24,'Revenue automotive'!N32,'Revenue automotive'!N40) -> 1 | O16: =CHOOSE(Drivers!$C$3,'Revenue automotive'!O24,'Revenue automotive'!O32,'Revenue automotive'!O40) -> 1 | ... Q16: =CHOOSE(Drivers!$C$3,'Revenue automotive'!Q24,'Revenue automotive'!Q32,'Revenue automotive'!Q40) -> 1
B17: Tesla Roadster 2 | H17: =CHOOSE(Drivers!$C$3,'Revenue automotive'!H25,'Revenue automotive'!H33,'Revenue automotive'!H41) -> 1 | I17: =CHOOSE(Drivers!$C$3,'Revenue automotive'!I25,'Revenue automotive'!I33,'Revenue automotive'!I41) -> 1 | J17: =CHOOSE(Drivers!$C$3,'Revenue automotive'!J25,'Revenue automotive'!J33,'Revenue automotive'!J41) -> 1 | K17: =CHOOSE(Drivers!$C$3,'Revenue automotive'!K25,'Revenue automotive'!K33,'Revenue automotive'!K41) -> 1 | L17: =CHOOSE(Drivers!$C$3,'Revenue automotive'!L25,'Revenue automotive'!L33,'Revenue automotive'!L41) -> 1 | M17: =CHOOSE(Drivers!$C$3,'Revenue automotive'!M25,'Revenue automotive'!M33,'Revenue automotive'!M41) -> 1 | N17: =CHOOSE(Drivers!$C$3,'Revenue automotive'!N25,'Revenue automotive'!N33,'Revenue automotive'!N41) -> 1 | O17: =CHOOSE(Drivers!$C$3,'Revenue automotive'!O25,'Revenue automotive'!O33,'Revenue automotive'!O41) -> 1 | ... Q17: =CHOOSE(Drivers!$C$3,'Revenue automotive'!Q25,'Revenue automotive'!Q33,'Revenue automotive'!Q41) -> 1
B18: Tesla Pickup | H18: =CHOOSE(Drivers!$C$3,'Revenue automotive'!H26,'Revenue automotive'!H34,'Revenue automotive'!H42) -> 1 | I18: =CHOOSE(Drivers!$C$3,'Revenue automotive'!I26,'Revenue automotive'!I34,'Revenue automotive'!I42) -> 1 | J18: =CHOOSE(Drivers!$C$3,'Revenue automotive'!J26,'Revenue automotive'!J34,'Revenue automotive'!J42) -> 1 | K18: =CHOOSE(Drivers!$C$3,'Revenue automotive'!K26,'Revenue automotive'!K34,'Revenue automotive'!K42) -> 1 | L18: =CHOOSE(Drivers!$C$3,'Revenue automotive'!L26,'Revenue automotive'!L34,'Revenue automotive'!L42) -> 1 | M18: =CHOOSE(Drivers!$C$3,'Revenue automotive'!M26,'Revenue automotive'!M34,'Revenue automotive'!M42) -> 1 | N18: =CHOOSE(Drivers!$C$3,'Revenue automotive'!N26,'Revenue automotive'!N34,'Revenue automotive'!N42) -> 1 | O18: =CHOOSE(Drivers!$C$3,'Revenue automotive'!O26,'Revenue automotive'!O34,'Revenue automotive'!O42) -> 1 | ... Q18: =CHOOSE(Drivers!$C$3,'Revenue automotive'!Q26,'Revenue automotive'!Q34,'Revenue automotive'!Q42) -> 1
B19: Tesla Semi | H19: =CHOOSE(Drivers!$C$3,'Revenue automotive'!H27,'Revenue automotive'!H35,'Revenue automotive'!H43) -> 1 | I19: =CHOOSE(Drivers!$C$3,'Revenue automotive'!I27,'Revenue automotive'!I35,'Revenue automotive'!I43) -> 1 | J19: =CHOOSE(Drivers!$C$3,'Revenue automotive'!J27,'Revenue automotive'!J35,'Revenue automotive'!J43) -> 1 | K19: =CHOOSE(Drivers!$C$3,'Revenue automotive'!K27,'Revenue automotive'!K35,'Revenue automotive'!K43) -> 1 | L19: =CHOOSE(Drivers!$C$3,'Revenue automotive'!L27,'Revenue automotive'!L35,'Revenue automotive'!L43) -> 1 | M19: =CHOOSE(Drivers!$C$3,'Revenue automotive'!M27,'Revenue automotive'!M35,'Revenue automotive'!M43) -> 1 | N19: =CHOOSE(Drivers!$C$3,'Revenue automotive'!N27,'Revenue automotive'!N35,'Revenue automotive'!N43) -> 1 | O19: =CHOOSE(Drivers!$C$3,'Revenue automotive'!O27,'Revenue automotive'!O35,'Revenue automotive'!O43) -> 1 | ... Q19: =CHOOSE(Drivers!$C$3,'Revenue automotive'!Q27,'Revenue automotive'!Q35,'Revenue automotive'!Q43) -> 1
B21: Best case
B22: Tesla Model 3 | H22: 1.02 | I22: 1.02 | J22: 1.02 | K22: 1.02 | L22: 1.02 | M22: 1.02 | N22: 1.02 | O22: 1.02 | P22: 1.02 | Q22: 1.02
B23: Tesla Model S and X | H23: 1.02 | I23: 1.02 | J23: 1.02 | K23: 1.02 | L23: 1.02 | M23: 1.02 | N23: 1.02 | O23: 1.02 | P23: 1.02 | Q23: 1.02
B24: Tesla Model Y | H24: 1.02 | I24: 1.02 | J24: 1.02 | K24: 1.02 | L24: 1.02 | M24: 1.02 | N24: 1.02 | O24: 1.02 | P24: 1.02 | Q24: 1.02
B25: Tesla Roadster 2 | H25: 1.02 | I25: 1.02 | J25: 1.02 | K25: 1.02 | L25: 1.02 | M25: 1.02 | N25: 1.02 | O25: 1.02 | P25: 1.02 | Q25: 1.02
B26: Tesla Pickup | H26: 1.02 | I26: 1.02 | J26: 1.02 | K26: 1.02 | L26: 1.02 | M26: 1.02 | N26: 1.02 | O26: 1.02 | P26: 1.02 | Q26: 1.02
B27: Tesla Semi | H27: 1.02 | I27: 1.02 | J27: 1.02 | K27: 1.02 | L27: 1.02 | M27: 1.02 | N27: 1.02 | O27: 1.02 | P27: 1.02 | Q27: 1.02
B29: Base case
B30: Tesla Model 3 | H30: 1 | I30: 1 | J30: 1 | K30: 1 | L30: 1 | M30: 1 | N30: 1 | O30: 1 | P30: 1 | Q30: 1
B31: Tesla Model S and X | H31: 1 | I31: 1 | J31: 1 | K31: 1 | L31: 1 | M31: 1 | N31: 1 | O31: 1 | P31: 1 | Q31: 1
B32: Tesla Model Y | H32: 1 | I32: 1 | J32: 1 | K32: 1 | L32: 1 | M32: 1 | N32: 1 | O32: 1 | P32: 1 | Q32: 1
B33: Tesla Roadster 2 | H33: 1 | I33: 1 | J33: 1 | K33: 1 | L33: 1 | M33: 1 | N33: 1 | O33: 1 | P33: 1 | Q33: 1
B34: Tesla Pickup | H34: 1 | I34: 1 | J34: 1 | K34: 1 | L34: 1 | M34: 1 | N34: 1 | O34: 1 | P34: 1 | Q34: 1
B35: Tesla Semi | H35: 1 | I35: 1 | J35: 1 | K35: 1 | L35: 1 | M35: 1 | N35: 1 | O35: 1 | P35: 1 | Q35: 1
B37: Worst case
B38: Tesla Model 3 | H38: 0.98 | I38: 0.98 | J38: 0.98 | K38: 0.98 | L38: 0.98 | M38: 0.98 | N38: 0.98 | O38: 0.98 | P38: 0.98 | Q38: 0.98
B39: Tesla Model S and X | H39: 0.98 | I39: 0.98 | J39: 0.98 | K39: 0.98 | L39: 0.98 | M39: 0.98 | N39: 0.98 | O39: 0.98 | P39: 0.98 | Q39: 0.98
B40: Tesla Model Y | H40: 0.98 | I40: 0.98 | J40: 0.98 | K40: 0.98 | L40: 0.98 | M40: 0.98 | N40: 0.98 | O40: 0.98 | P40: 0.98 | Q40: 0.98
B41: Tesla Roadster 2 | H41: 0.98 | I41: 0.98 | J41: 0.98 | K41: 0.98 | L41: 0.98 | M41: 0.98 | N41: 0.98 | O41: 0.98 | P41: 0.98 | Q41: 0.98
B42: Tesla Pickup | H42: 0.98 | I42: 0.98 | J42: 0.98 | K42: 0.98 | L42: 0.98 | M42: 0.98 | N42: 0.98 | O42: 0.98 | P42: 0.98 | Q42: 0.98
B43: Tesla Semi | H43: 0.98 | I43: 0.98 | J43: 0.98 | K43: 0.98 | L43: 0.98 | M43: 0.98 | N43: 0.98 | O43: 0.98 | P43: 0.98 | Q43: 0.98

Sheet GP% automotive
B1: GP %
B3: Comparables 2019
B5: Vehicle | C5: Comparable companies | D5: GP % Comp. 1 | E5: GP % Comp. 2 | F5: GP % Comp. 3 | H5: Average
B6: Tesla Model 3 | C6: GM, Ford, Fiat Chrysler | D6: 0.187 | E6: =(((155900-134693)/155900)+((160338-136269)/160338))/2 -> 0.14307182 | F6: =(((108187-93164)/108187)+((110412-95011)/110412))/2 -> 0.13917403 | H6: =C16 -> 0.22344388 | I6: Historic
B7: Tesla Model S and X | C7: BMW, Mercedes Cars, Volkswagen | D7: =((13620/91682)+(13928/85846))/2 -> 0.15540049 | E7: =((33067/167362)+(29165/172745))/2 -> 0.18320519 | F7: 0.172 | H7: =C17 -> 0.22344388 | I7: Historic
B8: Tesla Model Y | C8: GM, Ford, Fiat Chrysler | D8: 0.187 | E8: =(((155900-134693)/155900)+((160338-136269)/160338))/2 -> 0.14307182 | F8: =(((108187-93164)/108187)+((110412-95011)/110412))/2 -> 0.13917403 | H8: =AVERAGE(D8:F8) -> 0.15641528 | I8: Comparables
B9: Tesla Roadster 2 | C9: Jaguar, Porsche, Ferrari | D9: =(((24214-15670)/24214)+((25786-16328)/25786))/2 -> 0.35982095 | E9: 0.44 | F9: =(((3766-1805)/3766)+((3420-1623)/3420))/2 -> 0.52307511 | H9: =AVERAGE(D9:F9) -> 0.44096535 | I9: Comparables
B10: Tesla Pickup | C10: GM, Ford, Fiat Chrysler | D10: =D6 -> 0.187 | E10: =E6 -> 0.14307182 | F10: =F6 -> 0.13917403 | H10: =AVERAGE(D10:F10) -> 0.15641528 | I10: Comparables
B11: Tesla Semi | C11: Scania, MAN, Paccar | D11: 0.23 | E11: 0.23 | F11: =(((24120-20556)/24120)+((22139-18925)/22139))/2 -> 0.14646743 | H11: =AVERAGE(D11:F11) -> 0.20215581 | I11: Comparables
B13: Historical
B15: Vehicle | C15: Historic Average GP%
B16: Tesla Model 3 | C16: =AVERAGE('P&L Input'!F29:G29) -> 0.22344388
B17: Tesla Model S and X | C17: =AVERAGE('P&L Input'!F29:G29) -> 0.22344388
B18: Tesla Model Y | C18: n.a.
B19: Tesla Roadster 2 | C19: n.a.
B20: Tesla Pickup | C20: n.a.
B21: Tesla Semi | C21: n.a.

Sheet GP automotive
B1: Gross Profit
C3: Tesla Gross Profit (in mln $)
B4: Vehicle | C4: 2015 Act | D4: 2016 Act | E4: 2017 Act | F4: 2018 Act | G4: 2019 Act | H4: 2020 Fcst | I4: 2021 Fcst | J4: 2022 Fcst | K4: 2023 Fcst | L4: 2024 Fcst | M4: 2025 Fcst | N4: 2026 Fcst | O4: 2027 Fcst | P4: 2028 Fcst | Q4: 2029 Fcst
B5: Tesla Model 3 | C5: n.a. | D5: n.a. | E5: n.a. | F5: n.a. | G5: n.a. | H5: =H14*'Revenue automotive'!H5 -> 5824.2481 | I5: =I14*'Revenue automotive'!I5 -> 6406.6729 | J5: =J14*'Revenue automotive'!J5 -> 7047.3402 | K5: =K14*'Revenue automotive'!K5 -> 7611.1274 | L5: =L14*'Revenue automotive'!L5 -> 8220.0176 | M5: =M14*'Revenue automotive'!M5 -> 8548.8183 | N5: =N14*'Revenue automotive'!N5 -> 8890.771 | O5: =O14*'Revenue automotive'!O5 -> 9246.4019 | ... Q5: =Q14*'Revenue automotive'!Q5 -> 10000.908
B6: Tesla Model S and X | C6: n.a. | D6: n.a. | E6: n.a. | F6: n.a. | G6: n.a. | H6: =H15*'Revenue automotive'!H6 -> 1574.3287 | I6: =I15*'Revenue automotive'!I6 -> 1637.3019 | J6: =J15*'Revenue automotive'!J6 -> 1702.7939 | K6: =K15*'Revenue automotive'!K6 -> 1770.9057 | L6: =L15*'Revenue automotive'!L6 -> 1841.7419 | M6: =M15*'Revenue automotive'!M6 -> 1915.4116 | N6: =N15*'Revenue automotive'!N6 -> 1992.0281 | O6: =O15*'Revenue automotive'!O6 -> 2071.7092 | ... Q6: =Q15*'Revenue automotive'!Q6 -> 2240.7607
B7: Tesla Model Y | C7: 0 | D7: 0 | E7: 0 | F7: 0 | G7: =G16*'Revenue automotive'!G7 -> 0 | H7: =H16*'Revenue automotive'!H7 -> 16.83091 | I7: =I16*'Revenue automotive'!I7 -> 1393.5593 | J7: =J16*'Revenue automotive'!J7 -> 2870.1759 | K7: =K16*'Revenue automotive'!K7 -> 4592.2814 | L7: =L16*'Revenue automotive'!L7 -> 5051.5096 | M7: =M16*'Revenue automotive'!M7 -> 5556.6605 | N7: =N16*'Revenue automotive'!N7 -> 6001.1934 | ... Q7: =Q16*'Revenue automotive'!Q7 -> 7010.162
B8: Tesla Roadster 2 | C8: 0 | D8: 0 | E8: 0 | F8: 0 | G8: =G17*'Revenue automotive'!G8 -> 0 | H8: =H17*'Revenue automotive'!H8 -> 0 | I8: =I17*'Revenue automotive'!I8 -> 0 | J8: =J17*'Revenue automotive'!J8 -> 49.608602 | K8: =K17*'Revenue automotive'!K8 -> 99.217205 | L8: =L17*'Revenue automotive'!L8 -> 148.82581 | M8: =M17*'Revenue automotive'!M8 -> 163.70839 | N8: =N17*'Revenue automotive'!N8 -> 180.07923 | ... Q8: =Q17*'Revenue automotive'!Q8 -> 218.44619
B9: Tesla Pickup | C9: 0 | D9: 0 | E9: 0 | F9: 0 | G9: =G18*'Revenue automotive'!G9 -> 0 | H9: =H18*'Revenue automotive'!H9 -> 0 | I9: =I18*'Revenue automotive'!I9 -> 2.2836632 | J9: =J18*'Revenue automotive'!J9 -> 189.08187 | K9: =K18*'Revenue automotive'!K9 -> 389.43318 | L9: =L18*'Revenue automotive'!L9 -> 623.09309 | M9: =M18*'Revenue automotive'!M9 -> 685.4024 | N9: =N18*'Revenue automotive'!N9 -> 753.94264 | ... Q9: =Q18*'Revenue automotive'!Q9 -> 914.57464
B10: Tesla Semi | C10: 0 | D10: 0 | E10: 0 | F10: 0 | G10: =G19*'Revenue automotive'!G10 -> 0 | H10: =H19*'Revenue automotive'!H10 -> 0 | I10: =I19*'Revenue automotive'!I10 -> 8.8443168 | J10: =J19*'Revenue automotive'!J10 -> 732.28837 | K10: =K19*'Revenue automotive'!K10 -> 1508.2217 | L10: =L19*'Revenue automotive'!L10 -> 2413.1548 | M10: =M19*'Revenue automotive'!M10 -> 2654.4703 | N10: =N19*'Revenue automotive'!N10 -> 2919.9173 | ... Q10: =Q19*'Revenue automotive'!Q10 -> 3542.0232
B11: Total | C11: =('P&L Input'!C4+'P&L Input'!C8)/1000 -> 917.671 | D11: =('P&L Input'!D4+'P&L Input'!D8)/1000 -> 1600.685 | E11: =('P&L Input'!E4+'P&L Input'!E8)/1000 -> 2208.596 | F11: =('P&L Input'!F4+'P&L Input'!F8)/1000 -> 4340.986 | G11: =('P&L Input'!G4+'P&L Input'!G8)/1000 -> 4423 | H11: =SUM(H5:H10) -> 7415.4077 | I11: =SUM(I5:I10) -> 9448.662 | J11: =SUM(J5:J10) -> 12591.289 | K11: =SUM(K5:K10) -> 15971.187 | L11: =SUM(L5:L10) -> 18298.343 | M11: =SUM(M5:M10) -> 19524.471 | N11: =SUM(N5:N10) -> 20737.932 | O11: =SUM(O5:O10) -> 21961.654 | ... Q11: =SUM(Q5:Q10) -> 23926.875
B13: Selected case
B14: Tesla Model 3 | G14: =CHOOSE(Drivers!$C$3,'GP automotive'!G22,'GP automotive'!G30,'GP automotive'!G38) -> 0.22344388 | H14: =CHOOSE(Drivers!$C$3,'GP automotive'!H22,'GP automotive'!H30,'GP automotive'!H38) -> 0.22344388 | I14: =CHOOSE(Drivers!$C$3,'GP automotive'!I22,'GP automotive'!I30,'GP automotive'!I38) -> 0.22344388 | J14: =CHOOSE(Drivers!$C$3,'GP automotive'!J22,'GP automotive'!J30,'GP automotive'!J38) -> 0.22344388 | K14: =CHOOSE(Drivers!$C$3,'GP automotive'!K22,'GP automotive'!K30,'GP automotive'!K38) -> 0.22344388 | L14: =CHOOSE(Drivers!$C$3,'GP automotive'!L22,'GP automotive'!L30,'GP automotive'!L38) -> 0.22344388 | M14: =CHOOSE(Drivers!$C$3,'GP automotive'!M22,'GP automotive'!M30,'GP automotive'!M38) -> 0.22344388 | N14: =CHOOSE(Drivers!$C$3,'GP automotive'!N22,'GP automotive'!N30,'GP automotive'!N38) -> 0.22344388 | ... Q14: =CHOOSE(Drivers!$C$3,'GP automotive'!Q22,'GP automotive'!Q30,'GP automotive'!Q38) -> 0.22344388
B15: Tesla Model S and X | G15: =CHOOSE(Drivers!$C$3,'GP automotive'!G23,'GP automotive'!G31,'GP automotive'!G39) -> 0.22344388 | H15: =CHOOSE(Drivers!$C$3,'GP automotive'!H23,'GP automotive'!H31,'GP automotive'!H39) -> 0.22344388 | I15: =CHOOSE(Drivers!$C$3,'GP automotive'!I23,'GP automotive'!I31,'GP automotive'!I39) -> 0.22344388 | J15: =CHOOSE(Drivers!$C$3,'GP automotive'!J23,'GP automotive'!J31,'GP automotive'!J39) -> 0.22344388 | K15: =CHOOSE(Drivers!$C$3,'GP automotive'!K23,'GP automotive'!K31,'GP automotive'!K39) -> 0.22344388 | L15: =CHOOSE(Drivers!$C$3,'GP automotive'!L23,'GP automotive'!L31,'GP automotive'!L39) -> 0.22344388 | M15: =CHOOSE(Drivers!$C$3,'GP automotive'!M23,'GP automotive'!M31,'GP automotive'!M39) -> 0.22344388 | N15: =CHOOSE(Drivers!$C$3,'GP automotive'!N23,'GP automotive'!N31,'GP automotive'!N39) -> 0.22344388 | ... Q15: =CHOOSE(Drivers!$C$3,'GP automotive'!Q23,'GP automotive'!Q31,'GP automotive'!Q39) -> 0.22344388
B16: Tesla Model Y | G16: =CHOOSE(Drivers!$C$3,'GP automotive'!G24,'GP automotive'!G32,'GP automotive'!G40) -> 0.15641528 | H16: =CHOOSE(Drivers!$C$3,'GP automotive'!H24,'GP automotive'!H32,'GP automotive'!H40) -> 0.15641528 | I16: =CHOOSE(Drivers!$C$3,'GP automotive'!I24,'GP automotive'!I32,'GP automotive'!I40) -> 0.15641528 | J16: =CHOOSE(Drivers!$C$3,'GP automotive'!J24,'GP automotive'!J32,'GP automotive'!J40) -> 0.15641528 | K16: =CHOOSE(Drivers!$C$3,'GP automotive'!K24,'GP automotive'!K32,'GP automotive'!K40) -> 0.15641528 | L16: =CHOOSE(Drivers!$C$3,'GP automotive'!L24,'GP automotive'!L32,'GP automotive'!L40) -> 0.15641528 | M16: =CHOOSE(Drivers!$C$3,'GP automotive'!M24,'GP automotive'!M32,'GP automotive'!M40) -> 0.15641528 | N16: =CHOOSE(Drivers!$C$3,'GP automotive'!N24,'GP automotive'!N32,'GP automotive'!N40) -> 0.15641528 | ... Q16: =CHOOSE(Drivers!$C$3,'GP automotive'!Q24,'GP automotive'!Q32,'GP automotive'!Q40) -> 0.15641528
B17: Tesla Roadster 2 | G17: =CHOOSE(Drivers!$C$3,'GP automotive'!G25,'GP automotive'!G33,'GP automotive'!G41) -> 0.44096535 | H17: =CHOOSE(Drivers!$C$3,'GP automotive'!H25,'GP automotive'!H33,'GP automotive'!H41) -> 0.44096535 | I17: =CHOOSE(Drivers!$C$3,'GP automotive'!I25,'GP automotive'!I33,'GP automotive'!I41) -> 0.44096535 | J17: =CHOOSE(Drivers!$C$3,'GP automotive'!J25,'GP automotive'!J33,'GP automotive'!J41) -> 0.44096535 | K17: =CHOOSE(Drivers!$C$3,'GP automotive'!K25,'GP automotive'!K33,'GP automotive'!K41) -> 0.44096535 | L17: =CHOOSE(Drivers!$C$3,'GP automotive'!L25,'GP automotive'!L33,'GP automotive'!L41) -> 0.44096535 | M17: =CHOOSE(Drivers!$C$3,'GP automotive'!M25,'GP automotive'!M33,'GP automotive'!M41) -> 0.44096535 | N17: =CHOOSE(Drivers!$C$3,'GP automotive'!N25,'GP automotive'!N33,'GP automotive'!N41) -> 0.44096535 | ... Q17: =CHOOSE(Drivers!$C$3,'GP automotive'!Q25,'GP automotive'!Q33,'GP automotive'!Q41) -> 0.44096535
B18: Tesla Pickup | G18: =CHOOSE(Drivers!$C$3,'GP automotive'!G26,'GP automotive'!G34,'GP automotive'!G42) -> 0.15641528 | H18: =CHOOSE(Drivers!$C$3,'GP automotive'!H26,'GP automotive'!H34,'GP automotive'!H42) -> 0.15641528 | I18: =CHOOSE(Drivers!$C$3,'GP automotive'!I26,'GP automotive'!I34,'GP automotive'!I42) -> 0.15641528 | J18: =CHOOSE(Drivers!$C$3,'GP automotive'!J26,'GP automotive'!J34,'GP automotive'!J42) -> 0.15641528 | K18: =CHOOSE(Drivers!$C$3,'GP automotive'!K26,'GP automotive'!K34,'GP automotive'!K42) -> 0.15641528 | L18: =CHOOSE(Drivers!$C$3,'GP automotive'!L26,'GP automotive'!L34,'GP automotive'!L42) -> 0.15641528 | M18: =CHOOSE(Drivers!$C$3,'GP automotive'!M26,'GP automotive'!M34,'GP automotive'!M42) -> 0.15641528 | N18: =CHOOSE(Drivers!$C$3,'GP automotive'!N26,'GP automotive'!N34,'GP automotive'!N42) -> 0.15641528 | ... Q18: =CHOOSE(Drivers!$C$3,'GP automotive'!Q26,'GP automotive'!Q34,'GP automotive'!Q42) -> 0.15641528
B19: Tesla Semi | G19: =CHOOSE(Drivers!$C$3,'GP automotive'!G27,'GP automotive'!G35,'GP automotive'!G43) -> 0.20215581 | H19: =CHOOSE(Drivers!$C$3,'GP automotive'!H27,'GP automotive'!H35,'GP automotive'!H43) -> 0.20215581 | I19: =CHOOSE(Drivers!$C$3,'GP automotive'!I27,'GP automotive'!I35,'GP automotive'!I43) -> 0.20215581 | J19: =CHOOSE(Drivers!$C$3,'GP automotive'!J27,'GP automotive'!J35,'GP automotive'!J43) -> 0.20215581 | K19: =CHOOSE(Drivers!$C$3,'GP automotive'!K27,'GP automotive'!K35,'GP automotive'!K43) -> 0.20215581 | L19: =CHOOSE(Drivers!$C$3,'GP automotive'!L27,'GP automotive'!L35,'GP automotive'!L43) -> 0.20215581 | M19: =CHOOSE(Drivers!$C$3,'GP automotive'!M27,'GP automotive'!M35,'GP automotive'!M43) -> 0.20215581 | N19: =CHOOSE(Drivers!$C$3,'GP automotive'!N27,'GP automotive'!N35,'GP automotive'!N43) -> 0.20215581 | ... Q19: =CHOOSE(Drivers!$C$3,'GP automotive'!Q27,'GP automotive'!Q35,'GP automotive'!Q43) -> 0.20215581
B21: Best case
B22: Tesla Model 3 | G22: =G30+1.5% -> 0.23844388 | H22: =H30+1.5% -> 0.23844388 | I22: =I30+1.5% -> 0.23844388 | J22: =J30+1.5% -> 0.23844388 | K22: =K30+1.5% -> 0.23844388 | L22: =L30+1.5% -> 0.23844388 | M22: =M30+1.5% -> 0.23844388 | N22: =N30+1.5% -> 0.23844388 | ... Q22: =Q30+1.5% -> 0.23844388
B23: Tesla Model S and X | G23: =G31+1.5% -> 0.23844388 | H23: =H31+1.5% -> 0.23844388 | I23: =I31+1.5% -> 0.23844388 | J23: =J31+1.5% -> 0.23844388 | K23: =K31+1.5% -> 0.23844388 | L23: =L31+1.5% -> 0.23844388 | M23: =M31+1.5% -> 0.23844388 | N23: =N31+1.5% -> 0.23844388 | ... Q23: =Q31+1.5% -> 0.23844388
B24: Tesla Model Y | G24: =G32+1.5% -> 0.17141528 | H24: =H32+1.5% -> 0.17141528 | I24: =I32+1.5% -> 0.17141528 | J24: =J32+1.5% -> 0.17141528 | K24: =K32+1.5% -> 0.17141528 | L24: =L32+1.5% -> 0.17141528 | M24: =M32+1.5% -> 0.17141528 | N24: =N32+1.5% -> 0.17141528 | ... Q24: =Q32+1.5% -> 0.17141528
B25: Tesla Roadster 2 | G25: =G33+1.5% -> 0.45596535 | H25: =H33+1.5% -> 0.45596535 | I25: =I33+1.5% -> 0.45596535 | J25: =J33+1.5% -> 0.45596535 | K25: =K33+1.5% -> 0.45596535 | L25: =L33+1.5% -> 0.45596535 | M25: =M33+1.5% -> 0.45596535 | N25: =N33+1.5% -> 0.45596535 | ... Q25: =Q33+1.5% -> 0.45596535
B26: Tesla Pickup | G26: =G34+1.5% -> 0.17141528 | H26: =H34+1.5% -> 0.17141528 | I26: =I34+1.5% -> 0.17141528 | J26: =J34+1.5% -> 0.17141528 | K26: =K34+1.5% -> 0.17141528 | L26: =L34+1.5% -> 0.17141528 | M26: =M34+1.5% -> 0.17141528 | N26: =N34+1.5% -> 0.17141528 | ... Q26: =Q34+1.5% -> 0.17141528
B27: Tesla Semi | G27: =G35+1.5% -> 0.21715581 | H27: =H35+1.5% -> 0.21715581 | I27: =I35+1.5% -> 0.21715581 | J27: =J35+1.5% -> 0.21715581 | K27: =K35+1.5% -> 0.21715581 | L27: =L35+1.5% -> 0.21715581 | M27: =M35+1.5% -> 0.21715581 | N27: =N35+1.5% -> 0.21715581 | ... Q27: =Q35+1.5% -> 0.21715581
B29: Base case
B30: Tesla Model 3 | G30: ='GP% automotive'!$H6 -> 0.22344388 | H30: ='GP% automotive'!$H6 -> 0.22344388 | I30: ='GP% automotive'!$H6 -> 0.22344388 | J30: ='GP% automotive'!$H6 -> 0.22344388 | K30: ='GP% automotive'!$H6 -> 0.22344388 | L30: ='GP% automotive'!$H6 -> 0.22344388 | M30: ='GP% automotive'!$H6 -> 0.22344388 | N30: ='GP% automotive'!$H6 -> 0.22344388 | ... Q30: ='GP% automotive'!$H6 -> 0.22344388
B31: Tesla Model S and X | G31: ='GP% automotive'!$H7 -> 0.22344388 | H31: ='GP% automotive'!$H7 -> 0.22344388 | I31: ='GP% automotive'!$H7 -> 0.22344388 | J31: ='GP% automotive'!$H7 -> 0.22344388 | K31: ='GP% automotive'!$H7 -> 0.22344388 | L31: ='GP% automotive'!$H7 -> 0.22344388 | M31: ='GP% automotive'!$H7 -> 0.22344388 | N31: ='GP% automotive'!$H7 -> 0.22344388 | ... Q31: ='GP% automotive'!$H7 -> 0.22344388
B32: Tesla Model Y | G32: ='GP% automotive'!$H8 -> 0.15641528 | H32: ='GP% automotive'!$H8 -> 0.15641528 | I32: ='GP% automotive'!$H8 -> 0.15641528 | J32: ='GP% automotive'!$H8 -> 0.15641528 | K32: ='GP% automotive'!$H8 -> 0.15641528 | L32: ='GP% automotive'!$H8 -> 0.15641528 | M32: ='GP% automotive'!$H8 -> 0.15641528 | N32: ='GP% automotive'!$H8 -> 0.15641528 | ... Q32: ='GP% automotive'!$H8 -> 0.15641528
B33: Tesla Roadster 2 | G33: ='GP% automotive'!$H9 -> 0.44096535 | H33: ='GP% automotive'!$H9 -> 0.44096535 | I33: ='GP% automotive'!$H9 -> 0.44096535 | J33: ='GP% automotive'!$H9 -> 0.44096535 | K33: ='GP% automotive'!$H9 -> 0.44096535 | L33: ='GP% automotive'!$H9 -> 0.44096535 | M33: ='GP% automotive'!$H9 -> 0.44096535 | N33: ='GP% automotive'!$H9 -> 0.44096535 | ... Q33: ='GP% automotive'!$H9 -> 0.44096535
B34: Tesla Pickup | G34: ='GP% automotive'!$H10 -> 0.15641528 | H34: ='GP% automotive'!$H10 -> 0.15641528 | I34: ='GP% automotive'!$H10 -> 0.15641528 | J34: ='GP% automotive'!$H10 -> 0.15641528 | K34: ='GP% automotive'!$H10 -> 0.15641528 | L34: ='GP% automotive'!$H10 -> 0.15641528 | M34: ='GP% automotive'!$H10 -> 0.15641528 | N34: ='GP% automotive'!$H10 -> 0.15641528 | ... Q34: ='GP% automotive'!$H10 -> 0.15641528
B35: Tesla Semi | G35: ='GP% automotive'!$H11 -> 0.20215581 | H35: ='GP% automotive'!$H11 -> 0.20215581 | I35: ='GP% automotive'!$H11 -> 0.20215581 | J35: ='GP% automotive'!$H11 -> 0.20215581 | K35: ='GP% automotive'!$H11 -> 0.20215581 | L35: ='GP% automotive'!$H11 -> 0.20215581 | M35: ='GP% automotive'!$H11 -> 0.20215581 | N35: ='GP% automotive'!$H11 -> 0.20215581 | ... Q35: ='GP% automotive'!$H11 -> 0.20215581
B37: Worst case
B38: Tesla Model 3 | G38: =G30-1.5% -> 0.20844388 | H38: =H30-1.5% -> 0.20844388 | I38: =I30-1.5% -> 0.20844388 | J38: =J30-1.5% -> 0.20844388 | K38: =K30-1.5% -> 0.20844388 | L38: =L30-1.5% -> 0.20844388 | M38: =M30-1.5% -> 0.20844388 | N38: =N30-1.5% -> 0.20844388 | ... Q38: =Q30-1.5% -> 0.20844388
B39: Tesla Model S and X | G39: =G31-1.5% -> 0.20844388 | H39: =H31-1.5% -> 0.20844388 | I39: =I31-1.5% -> 0.20844388 | J39: =J31-1.5% -> 0.20844388 | K39: =K31-1.5% -> 0.20844388 | L39: =L31-1.5% -> 0.20844388 | M39: =M31-1.5% -> 0.20844388 | N39: =N31-1.5% -> 0.20844388 | ... Q39: =Q31-1.5% -> 0.20844388
B40: Tesla Model Y | G40: =G32-1.5% -> 0.14141528 | H40: =H32-1.5% -> 0.14141528 | I40: =I32-1.5% -> 0.14141528 | J40: =J32-1.5% -> 0.14141528 | K40: =K32-1.5% -> 0.14141528 | L40: =L32-1.5% -> 0.14141528 | M40: =M32-1.5% -> 0.14141528 | N40: =N32-1.5% -> 0.14141528 | ... Q40: =Q32-1.5% -> 0.14141528
B41: Tesla Roadster 2 | G41: =G33-1.5% -> 0.42596535 | H41: =H33-1.5% -> 0.42596535 | I41: =I33-1.5% -> 0.42596535 | J41: =J33-1.5% -> 0.42596535 | K41: =K33-1.5% -> 0.42596535 | L41: =L33-1.5% -> 0.42596535 | M41: =M33-1.5% -> 0.42596535 | N41: =N33-1.5% -> 0.42596535 | ... Q41: =Q33-1.5% -> 0.42596535
B42: Tesla Pickup | G42: =G34-1.5% -> 0.14141528 | H42: =H34-1.5% -> 0.14141528 | I42: =I34-1.5% -> 0.14141528 | J42: =J34-1.5% -> 0.14141528 | K42: =K34-1.5% -> 0.14141528 | L42: =L34-1.5% -> 0.14141528 | M42: =M34-1.5% -> 0.14141528 | N42: =N34-1.5% -> 0.14141528 | ... Q42: =Q34-1.5% -> 0.14141528
B43: Tesla Semi | G43: =G35-1.5% -> 0.18715581 | H43: =H35-1.5% -> 0.18715581 | I43: =I35-1.5% -> 0.18715581 | J43: =J35-1.5% -> 0.18715581 | K43: =K35-1.5% -> 0.18715581 | L43: =L35-1.5% -> 0.18715581 | M43: =M35-1.5% -> 0.18715581 | N43: =N35-1.5% -> 0.18715581 | ... Q43: =Q35-1.5% -> 0.18715581

Sheet Cost of sales automotive
B1: Cost of sales automotive
C3: Tesla Cost of sales (in mln $)
B4: Vehicle | C4: 2015 Act | D4: 2016 Act | E4: 2017 Act | F4: 2018 Act | G4: 2019 Act | H4: 2020 Fcst | I4: 2021 Fcst | J4: 2022 Fcst | K4: 2023 Fcst | L4: 2024 Fcst | M4: 2025 Fcst | N4: 2026 Fcst | O4: 2027 Fcst | P4: 2028 Fcst | Q4: 2029 Fcst
B5: Tesla Model 3 | C5: n.a. | D5: n.a. | E5: n.a. | F5: n.a. | G5: n.a. | H5: =-('Revenue automotive'!H5-'GP automotive'!H5) -> -20241.572 | I5: =-('Revenue automotive'!I5-'GP automotive'!I5) -> -22265.729 | J5: =-('Revenue automotive'!J5-'GP automotive'!J5) -> -24492.302 | K5: =-('Revenue automotive'!K5-'GP automotive'!K5) -> -26451.687 | L5: =-('Revenue automotive'!L5-'GP automotive'!L5) -> -28567.821 | M5: =-('Revenue automotive'!M5-'GP automotive'!M5) -> -29710.534 | N5: =-('Revenue automotive'!N5-'GP automotive'!N5) -> -30898.956 | O5: =-('Revenue automotive'!O5-'GP automotive'!O5) -> -32134.914 | ... Q5: =-('Revenue automotive'!Q5-'GP automotive'!Q5) -> -34757.123
B6: Tesla Model S and X | C6: n.a. | D6: n.a. | E6: n.a. | F6: n.a. | G6: n.a. | H6: =-('Revenue automotive'!H6-'GP automotive'!H6) -> -5471.4167 | I6: =-('Revenue automotive'!I6-'GP automotive'!I6) -> -5690.2734 | J6: =-('Revenue automotive'!J6-'GP automotive'!J6) -> -5917.8843 | K6: =-('Revenue automotive'!K6-'GP automotive'!K6) -> -6154.5997 | L6: =-('Revenue automotive'!L6-'GP automotive'!L6) -> -6400.7837 | M6: =-('Revenue automotive'!M6-'GP automotive'!M6) -> -6656.815 | N6: =-('Revenue automotive'!N6-'GP automotive'!N6) -> -6923.0876 | O6: =-('Revenue automotive'!O6-'GP automotive'!O6) -> -7200.0111 | ... Q6: =-('Revenue automotive'!Q6-'GP automotive'!Q6) -> -7787.532
B7: Tesla Model Y | C7: 0 | D7: 0 | E7: 0 | F7: 0 | G7: =-('Revenue automotive'!G7-'GP automotive'!G7) -> 0 | H7: =-('Revenue automotive'!H7-'GP automotive'!H7) -> -90.77309 | I7: =-('Revenue automotive'!I7-'GP automotive'!I7) -> -7515.7957 | J7: =-('Revenue automotive'!J7-'GP automotive'!J7) -> -15479.539 | K7: =-('Revenue automotive'!K7-'GP automotive'!K7) -> -24767.263 | L7: =-('Revenue automotive'!L7-'GP automotive'!L7) -> -27243.989 | M7: =-('Revenue automotive'!M7-'GP automotive'!M7) -> -29968.388 | N7: =-('Revenue automotive'!N7-'GP automotive'!N7) -> -32365.859 | ... Q7: =-('Revenue automotive'!Q7-'GP automotive'!Q7) -> -37807.466
B8: Tesla Roadster 2 | C8: 0 | D8: 0 | E8: 0 | F8: 0 | G8: =-('Revenue automotive'!G8-'GP automotive'!G8) -> 0 | H8: =-('Revenue automotive'!H8-'GP automotive'!H8) -> 0 | I8: =-('Revenue automotive'!I8-'GP automotive'!I8) -> 0 | J8: =-('Revenue automotive'!J8-'GP automotive'!J8) -> -62.891398 | K8: =-('Revenue automotive'!K8-'GP automotive'!K8) -> -125.7828 | L8: =-('Revenue automotive'!L8-'GP automotive'!L8) -> -188.67419 | M8: =-('Revenue automotive'!M8-'GP automotive'!M8) -> -207.54161 | N8: =-('Revenue automotive'!N8-'GP automotive'!N8) -> -228.29577 | ... Q8: =-('Revenue automotive'!Q8-'GP automotive'!Q8) -> -276.93556
B9: Tesla Pickup | C9: 0 | D9: 0 | E9: 0 | F9: 0 | G9: =-('Revenue automotive'!G9-'GP automotive'!G9) -> 0 | H9: =-('Revenue automotive'!H9-'GP automotive'!H9) -> 0 | I9: =-('Revenue automotive'!I9-'GP automotive'!I9) -> -12.316337 | J9: =-('Revenue automotive'!J9-'GP automotive'!J9) -> -1019.7634 | K9: =-('Revenue automotive'!K9-'GP automotive'!K9) -> -2100.3055 | L9: =-('Revenue automotive'!L9-'GP automotive'!L9) -> -3360.4888 | M9: =-('Revenue automotive'!M9-'GP automotive'!M9) -> -3696.5376 | N9: =-('Revenue automotive'!N9-'GP automotive'!N9) -> -4066.1914 | ... Q9: =-('Revenue automotive'!Q9-'GP automotive'!Q9) -> -4932.5179
B10: Tesla Semi | C10: 0 | D10: 0 | E10: 0 | F10: 0 | G10: =-('Revenue automotive'!G10-'GP automotive'!G10) -> 0 | H10: =-('Revenue automotive'!H10-'GP automotive'!H10) -> 0 | I10: =-('Revenue automotive'!I10-'GP automotive'!I10) -> -34.905683 | J10: =-('Revenue automotive'!J10-'GP automotive'!J10) -> -2890.1075 | K10: =-('Revenue automotive'!K10-'GP automotive'!K10) -> -5952.4677 | L10: =-('Revenue automotive'!L10-'GP automotive'!L10) -> -9523.9484 | M10: =-('Revenue automotive'!M10-'GP automotive'!M10) -> -10476.343 | N10: =-('Revenue automotive'!N10-'GP automotive'!N10) -> -11523.978 | ... Q10: =-('Revenue automotive'!Q10-'GP automotive'!Q10) -> -13979.23
B11: Total | C11: ='P&L Input'!C8/1000 -> -2823.302 | D11: ='P&L Input'!D8/1000 -> -4750.081 | E11: ='P&L Input'!E8/1000 -> -7432.704 | F11: ='P&L Input'!F8/1000 -> -14173.997 | G11: =-('Revenue automotive'!G11-'GP automotive'!G11) -> -16398 | H11: =SUM(H5:H10) -> -25803.762 | I11: =SUM(I5:I10) -> -35519.021 | J11: =SUM(J5:J10) -> -49862.488 | K11: =SUM(K5:K10) -> -65552.105 | L11: =SUM(L5:L10) -> -75285.705 | M11: =SUM(M5:M10) -> -80716.16 | N11: =SUM(N5:N10) -> -86006.367 | O11: =SUM(O5:O10) -> -91373.994 | ... Q11: =SUM(Q5:Q10) -> -99540.804

Sheet Revenue & GP autom
B1: Revenue and Gross Profit automotive
B3: Vehicle | C3: 2016 Act | D3: 2017 Act | E3: 2018 Act | F3: 2019 Act | G3: 2020 Fcst | H3: 2021 Fcst | I3: 2022 Fcst | J3: 2023 Fcst | K3: 2024 Fcst | L3: 2025 Fcst | M3: 2026 Fcst | N3: 2027 Fcst | O3: 2028 Fcst | P3: 2029 Fcst
B4: Revenue automotive | C4: ='Revenue automotive'!C11 -> 3740.973 | D4: ='Revenue automotive'!D11 -> 6350.766 | E4: ='Revenue automotive'!E11 -> 9641.3 | F4: ='Revenue automotive'!F11 -> 18514.983 | G4: ='Revenue automotive'!H11 -> 33219.17 | H4: ='Revenue automotive'!I11 -> 44967.683 | I4: ='Revenue automotive'!J11 -> 62453.777 | J4: ='Revenue automotive'!K11 -> 81523.291 | K4: ='Revenue automotive'!L11 -> 93584.048 | L4: ='Revenue automotive'!M11 -> 100240.63 | M4: ='Revenue automotive'!N11 -> 106744.3 | N4: ='Revenue automotive'!O11 -> 113335.65 | ... P4: ='Revenue automotive'!Q11 -> 123467.68
B5: Gross Profit automotive | C5: ='GP automotive'!C11 -> 917.671 | D5: ='GP automotive'!D11 -> 1600.685 | E5: ='GP automotive'!E11 -> 2208.596 | F5: ='GP automotive'!F11 -> 4340.986 | G5: ='GP automotive'!H11 -> 7415.4077 | H5: ='GP automotive'!I11 -> 9448.662 | I5: ='GP automotive'!J11 -> 12591.289 | J5: ='GP automotive'!K11 -> 15971.187 | K5: ='GP automotive'!L11 -> 18298.343 | L5: ='GP automotive'!M11 -> 19524.471 | M5: ='GP automotive'!N11 -> 20737.932 | N5: ='GP automotive'!O11 -> 21961.654 | ... P5: ='GP automotive'!Q11 -> 23926.875
B6: GP% | C6: =C5/C4 -> 0.24530276 | D6: =D5/D4 -> 0.25204597 | E6: =E5/E4 -> 0.22907658 | F6: =F5/F4 -> 0.23445801 | G6: =G5/G4 -> 0.22322676 | H6: =H5/H4 -> 0.21012117 | I6: =I5/I4 -> 0.20160973 | J6: =J5/J4 -> 0.19590949 | ... P6: =P5/P4 -> 0.19379059

Sheet Energy & Other
B14: Energy & Other

Sheet Revenue Energy & Other
B1: Revenue Energy & Other
C3: Tesla Revenue Energy & Other (in mln $)
B4: ($ in million) | C4: 2015 Act | D4: 2016 Act | E4: 2017 Act | F4: 2018 Act | G4: 2019 Act | H4: 2020 Fcst | I4: 2021 Fcst | J4: 2022 Fcst | K4: 2023 Fcst | L4: 2024 Fcst | M4: 2025 Fcst | N4: 2026 Fcst | O4: 2027 Fcst | P4: 2028 Fcst | Q4: 2029 Fcst
B5: Energy generation and storage | C5: ='P&L Input'!C5/1000 -> 14.477 | D5: ='P&L Input'!D5/1000 -> 181.394 | E5: ='P&L Input'!E5/1000 -> 1116.266 | F5: ='P&L Input'!F5/1000 -> 1555.244 | G5: ='P&L Input'!G5/1000 -> 1531 | H5: n.a. | I5: n.a. | J5: n.a. | K5: n.a. | L5: n.a. | M5: n.a. | N5: n.a. | O5: n.a. | P5: n.a. | Q5: n.a.
B6: Services and other | C6: ='P&L Input'!C6/1000 -> 290.575 | D6: ='P&L Input'!D6/1000 -> 467.972 | E6: ='P&L Input'!E6/1000 -> 1001.185 | F6: ='P&L Input'!F6/1000 -> 1391.041 | G6: ='P&L Input'!G6/1000 -> 2226 | H6: n.a. | I6: n.a. | J6: n.a. | K6: n.a. | L6: n.a. | M6: n.a. | N6: n.a. | O6: n.a. | P6: n.a. | Q6: n.a.
B7: Total Energy and Other | C7: =SUM(C5:C6) -> 305.052 | D7: =SUM(D5:D6) -> 649.366 | E7: =SUM(E5:E6) -> 2117.451 | F7: =SUM(F5:F6) -> 2946.285 | G7: =SUM(G5:G6) -> 3757 | H7: =G7*(1+H10) -> 4433.26 | I7: =H7*(1+I10) -> 4965.2512 | J7: =I7*(1+J10) -> 5362.4713 | K7: =J7*(1+K10) -> 5684.2196 | L7: =K7*(1+L10) -> 6025.2727 | M7: =L7*(1+M10) -> 6386.7891 | N7: =M7*(1+N10) -> 6769.9965 | O7: =N7*(1+O10) -> 7176.1962 | ... Q7: =P7*(1+Q10) -> 8063.1741
B9: Selected case
B10: Total Energy and Other | H10: =CHOOSE(Drivers!$C$3,'Revenue Energy & Other'!H14,'Revenue Energy & Other'!H17,'Revenue Energy & Other'!H20) -> 0.18 | I10: =CHOOSE(Drivers!$C$3,'Revenue Energy & Other'!I14,'Revenue Energy & Other'!I17,'Revenue Energy & Other'!I20) -> 0.12 | J10: =CHOOSE(Drivers!$C$3,'Revenue Energy & Other'!J14,'Revenue Energy & Other'!J17,'Revenue Energy & Other'!J20) -> 0.08 | K10: =CHOOSE(Drivers!$C$3,'Revenue Energy & Other'!K14,'Revenue Energy & Other'!K17,'Revenue Energy & Other'!K20) -> 0.06 | L10: =CHOOSE(Drivers!$C$3,'Revenue Energy & Other'!L14,'Revenue Energy & Other'!L17,'Revenue Energy & Other'!L20) -> 0.06 | M10: =CHOOSE(Drivers!$C$3,'Revenue Energy & Other'!M14,'Revenue Energy & Other'!M17,'Revenue Energy & Other'!M20) -> 0.06 | N10: =CHOOSE(Drivers!$C$3,'Revenue Energy & Other'!N14,'Revenue Energy & Other'!N17,'Revenue Energy & Other'!N20) -> 0.06 | O10: =CHOOSE(Drivers!$C$3,'Revenue Energy & Other'!O14,'Revenue Energy & Other'!O17,'Revenue Energy & Other'!O20) -> 0.06 | ... Q10: =CHOOSE(Drivers!$C$3,'Revenue Energy & Other'!Q14,'Revenue Energy & Other'!Q17,'Revenue Energy & Other'!Q20) -> 0.06
B12: Y-o-Y %
B13: Best case
B14: Total Energy and Other | H14: =H17+Drivers!$C$13 -> 0.2 | I14: =I17+Drivers!$C$13 -> 0.14 | J14: =J17+Drivers!$C$13 -> 0.1 | K14: =K17+Drivers!$C$13 -> 0.08 | L14: =L17+Drivers!$C$13 -> 0.08 | M14: =M17+Drivers!$C$13 -> 0.08 | N14: =N17+Drivers!$C$13 -> 0.08 | O14: =O17+Drivers!$C$13 -> 0.08 | ... Q14: =Q17+Drivers!$C$13 -> 0.08
B16: Base case
B17: Total Energy and Other | D17: =D7/C7-1 -> 1.1287059 | E17: =E7/D7-1 -> 2.2607975 | F17: =F7/E7-1 -> 0.39143007 | G17: =G7/F7-1 -> 0.27516517 | H17: 0.18 | I17: 0.12 | J17: 0.08 | K17: 0.06 | L17: 0.06 | M17: 0.06 | N17: 0.06 | O17: 0.06 | P17: 0.06 | Q17: 0.06
B19: Worst case
B20: Total Energy and Other | H20: =H17-Drivers!$C$13 -> 0.16 | I20: =I17-Drivers!$C$13 -> 0.1 | J20: =J17-Drivers!$C$13 -> 0.06 | K20: =K17-Drivers!$C$13 -> 0.04 | L20: =L17-Drivers!$C$13 -> 0.04 | M20: =M17-Drivers!$C$13 -> 0.04 | N20: =N17-Drivers!$C$13 -> 0.04 | O20: =O17-Drivers!$C$13 -> 0.04 | ... Q20: =Q17-Drivers!$C$13 -> 0.04

Sheet GP Energy & Other
B1: Gross Profit Energy & Other
C3: Tesla GP% Energy and Other (in mln $)
B4: ($ in million) | C4: 2015 Act | D4: 2016 Act | E4: 2017 Act | F4: 2018 Act | G4: 2019 Act | H4: 2019 Fcst | I4: 2021 Fcst | J4: 2022 Fcst | K4: 2023 Fcst | L4: 2024 Fcst | M4: 2025 Fcst | N4: 2025 Fcst | O4: 2027 Fcst | P4: 2028 Fcst | Q4: 2029 Fcst
B5: Energy generation and storage | C5: =('P&L Input'!C5+'P&L Input'!C9)/1000 -> 2.19 | D5: =('P&L Input'!D5+'P&L Input'!D9)/1000 -> 3.062 | E5: =('P&L Input'!E5+'P&L Input'!E9)/1000 -> 241.728 | F5: =('P&L Input'!F5+'P&L Input'!F9)/1000 -> 190.348 | G5: =('P&L Input'!G5+'P&L Input'!G9)/1000 -> 190 | H5: n.a. | I5: n.a. | J5: n.a. | K5: n.a. | L5: n.a. | M5: n.a. | N5: n.a. | O5: n.a. | P5: n.a. | Q5: n.a.
B6: Services and other | C6: =('P&L Input'!C6+'P&L Input'!C10)/1000 -> 3.642 | D6: =('P&L Input'!D6+'P&L Input'!D10)/1000 -> -4.49 | E6: =('P&L Input'!E6+'P&L Input'!E10)/1000 -> -227.837 | F6: =('P&L Input'!F6+'P&L Input'!F10)/1000 -> -489.313 | G6: =('P&L Input'!G6+'P&L Input'!G10)/1000 -> -544 | H6: n.a. | I6: n.a. | J6: n.a. | K6: n.a. | L6: n.a. | M6: n.a. | N6: n.a. | O6: n.a. | P6: n.a. | Q6: n.a.
B7: Total Energy and Other | C7: =SUM(C5:C6) -> 5.832 | D7: =SUM(D5:D6) -> -1.428 | E7: =SUM(E5:E6) -> 13.891 | F7: =SUM(F5:F6) -> -298.965 | G7: =SUM(G5:G6) -> -354 | H7: =H11*'Revenue Energy & Other'!H7 -> 0 | I7: =I11*'Revenue Energy & Other'!I7 -> 0 | J7: =J11*'Revenue Energy & Other'!J7 -> 0 | K7: =K11*'Revenue Energy & Other'!K7 -> 0 | L7: =L11*'Revenue Energy & Other'!L7 -> 0 | M7: =M11*'Revenue Energy & Other'!M7 -> 0 | N7: =N11*'Revenue Energy & Other'!N7 -> 0 | O7: =O11*'Revenue Energy & Other'!O7 -> 0 | ... Q7: =Q11*'Revenue Energy & Other'!Q7 -> 0
B10: Selected case
