Workbook

Sheet Cover
B9: Tesla
B10: Company analysis

Sheet Drivers
B1: Drivers
B3: Selected case | C3: 2
B4: Company | C4: Tesla
B5: Currency | C5: USD
B6: Domestic country | C6: United States
B7: 10-year treasury yield (Sep 18 2020) | C7: 0.00697
B8: Market risk premium US | C8: 0.05
B9: Company beta (Dec 15 2020) | C9: 2.15
B10: Tesla share price (Dec 15 2020) | C10: 639.83
B11: Bond Yield (Sep 18 2020) | C11: 0.04324
B12: Corporate tax rate | C12: 0.21
B13: Expected inflation | C13: 0.02

Sheet Input -->
B14: Input -->

Sheet P&L Input
B1: P&L Input
B3: (in thousands) | C3: 2015 Act | D3: 2016 Act | E3: 2017 Act | F3: 2018 Act | G3: 2019 Act
B4: Automotive revenues | C4: 3740973 | D4: 6350766 | E4: 9641300 | F4: 18514983 | G4: 20821000
B5: Energy generation and storage | C5: 14477 | D5: 181394 | E5: 1116266 | F5: 1555244 | G5: 1531000
B6: Services and other | C6: 290575 | D6: 467972 | E6: 1001185 | F6: 1391041 | G6: 2226000
B7: Total revenues | C7: =SUM(C4:C6) -> 4046025 | D7: =SUM(D4:D6) -> 7000132 | E7: =SUM(E4:E6) -> 11758751 | F7: =SUM(F4:F6) -> 21461268 | G7: =SUM(G4:G6) -> 24578000
B8: Automotive cost of revenues | C8: -2823302 | D8: -4750081 | E8: -7432704 | F8: -14173997 | G8: -16398000
B9: Energy generation and storage cost of revenues | C9: -12287 | D9: -178332 | E9: -874538 | F9: -1364896 | G9: -1341000
B10: Services and other cost of revenues | C10: -286933 | D10: -472462 | E10: -1229022 | F10: -1880354 | G10: -2770000
B11: Gross profit | C11: =SUM(C7:C10) -> 923503 | D11: =SUM(D7:D10) -> 1599257 | E11: =SUM(E7:E10) -> 2222487 | F11: =SUM(F7:F10) -> 4042021 | G11: =SUM(G7:G10) -> 4069000
B12: Research and development | C12: -717900 | D12: -834408 | E12: -1378073 | F12: -1460370 | G12: -1343000
B13: Selling, general and administrative | C13: -922232 | D13: -1432189 | E13: -2476500 | F13: -2834491 | G13: -2646000
B14: Restructuring and other | F14: -135233 | G14: -149000
B15: EBIT | C15: =SUM(C11:C14) -> -716629 | D15: =SUM(D11:D14) -> -667340 | E15: =SUM(E11:E14) -> -1632086 | F15: =SUM(F11:F14) -> -388073 | G15: =SUM(G11:G14) -> -69000
B16: Interest income | C16: 1508 | D16: 8530 | E16: 19686 | F16: 24533 | G16: 44000
B17: Interest expense | C17: -118851 | D17: -198810 | E17: -471259 | F17: -663071 | G17: -685000
B18: Other income (expense), net | C18: -41652 | D18: 111272 | E18: -125373 | F18: 21866 | G18: 45000
B19: EBT | C19: =SUM(C15:C18) -> -875624 | D19: =SUM(D15:D18) -> -746348 | E19: =SUM(E15:E18) -> -2209032 | F19: =SUM(F15:F18) -> -1004745 | G19: =SUM(G15:G18) -> -665000
B20: Provision for income taxes | C20: -13039 | D20: -26698 | E20: -31546 | F20: -57837 | G20: -110000
B21: Net loss incl. minority interests | C21: =SUM(C19:C20) -> -888663 | D21: =SUM(D19:D20) -> -773046 | E21: =SUM(E19:E20) -> -2240578 | F21: =SUM(F19:F20) -> -1062582 | G21: =SUM(G19:G20) -> -775000
B22: Minority interests | C22: 0 | D22: 98132 | E22: 279178 | F22: 86491 | G22: -87000
B23: Net loss | C23: =SUM(C21:C22) -> -888663 | D23: =SUM(D21:D22) -> -674914 | E23: =SUM(E21:E22) -> -1961400 | F23: =SUM(F21:F22) -> -976091 | G23: =SUM(G21:G22) -> -862000
B25: KPIs
B26: Revenue % automotive y-o-y | D26: =D4/C4-1 -> 0.69762412 | E26: =E4/D4-1 -> 0.51813183 | F26: =F4/E4-1 -> 0.92038242 | G26: =G4/F4-1 -> 0.1245487
B27: Revenue % generation y-o-y | D27: =D5/C5-1 -> 11.529806 | E27: =E5/D5-1 -> 5.1538199 | F27: =F5/E5-1 -> 0.39325573 | G27: =G5/F5-1 -> -0.015588551
B28: Revenue % services y-o-y | D28: =D6/C6-1 -> 0.61050331 | E28: =E6/D6-1 -> 1.1394122 | F28: =F6/E6-1 -> 0.38939457 | G28: =G6/F6-1 -> 0.6002404
B29: GP% automotive | C29: =(C4+C8)/C4 -> 0.24530276 | D29: =(D4+D8)/D4 -> 0.25204597 | E29: =(E4+E8)/E4 -> 0.22907658 | F29: =(F4+F8)/F4 -> 0.23445801 | G29: =(G4+G8)/G4 -> 0.21242976
B30: GP% energy generation and automotive | C30: =(C5+C9)/C5 -> 0.15127444 | D30: =(D5+D9)/D5 -> 0.016880382 | E30: =(E5+E9)/E5 -> 0.21655054 | F30: =(F5+F9)/F5 -> 0.12239108 | G30: =(G5+G9)/G5 -> 0.12410189
B31: GP% services and other | C31: =(C6+C10)/C6 -> 0.012533769 | D31: =(D6+D10)/D6 -> -0.0095945911 | E31: =(E6+E10)/E6 -> -0.22756733 | F31: =(F6+F10)/F6 -> -0.3517603 | G31: =(G6+G10)/G6 -> -0.24438455
B32: Overall GP% | C32: =(SUM(C4:C6)+SUM(C8:C10))/SUM(C4:C6) -> 0.22824945 | D32: =(SUM(D4:D6)+SUM(D8:D10))/SUM(D4:D6) -> 0.22846098 | E32: =(SUM(E4:E6)+SUM(E8:E10))/SUM(E4:E6) -> 0.18900706 | F32: =(SUM(F4:F6)+SUM(F8:F10))/SUM(F4:F6) -> 0.18834027 | G32: =(SUM(G4:G6)+SUM(G8:G10))/SUM(G4:G6) -> 0.16555456
B33: EBIT % | C33: =C15/C7 -> -0.17711927 | D33: =D15/D7 -> -0.095332488 | E33: =E15/E7 -> -0.13879756 | F33: =F15/F7 -> -0.018082482 | G33: =G15/G7 -> -0.0028073887
B34: Net loss % | C34: =C23/C7 -> -0.21963853 | D34: =D23/D7 -> -0.096414468 | E34: =E23/E7 -> -0.16680343 | F34: =F23/F7 -> -0.045481516 | G34: =G23/G7 -> -0.035072016
B35: ROA | C35: =C23/'Balance Sheet Input'!C18 -> -0.11014746 | D35: =D23/'Balance Sheet Input'!D18 -> -0.029779021 | E35: =E23/'Balance Sheet Input'!E18 -> -0.068447899 | F35: =F23/'Balance Sheet Input'!F18 -> -0.03282124 | G35: =G23/'Balance Sheet Input'!G18 -> -0.025124603
B36: ROE | C36: =C23/'Balance Sheet Input'!C32 -> -0.82002373 | D36: =D23/'Balance Sheet Input'!D32 -> -0.14200013 | E36: =E23/'Balance Sheet Input'!E32 -> -0.46289544 | F36: =F23/'Balance Sheet Input'!F32 -> -0.1982618 | G36: =G23/'Balance Sheet Input'!G32 -> -0.13025083

Sheet Balance Sheet Input
B1: Balance Sheet Input
B3: (in thousands) | C3: 31 Dec 2015 | D3: 31 Dec 2016 | E3: 31 Dec 2017 | F3: 31 Dec 2018 | G3: 31 Dec 2019
B4: Cash and cash equivalents | C4: 1196908 | D4: 3393216 | E4: 3367914 | F4: 3685618 | G4: 6268000
B5: Restricted cash and marketable securities | C5: 22628 | D5: 105519 | E5: 155323 | F5: 192551 | G5: 246000
B6: Accounts receivable, net | C6: 168965 | D6: 499142 | E6: 515381 | F6: 949022 | G6: 1324000
B7: Inventory | C7: 1277838 | D7: 2067454 | E7: 2263537 | F7: 3113446 | G7: 3552000
B8: Prepaid expenses and other current assets | C8: 115667 | D8: 194465 | E8: 268365 | F8: 365671 | G8: 713000
B9: Total current assets | C9: =SUM(C4:C8) -> 2782006 | D9: =SUM(D4:D8) -> 6259796 | E9: =SUM(E4:E8) -> 6570520 | F9: =SUM(F4:F8) -> 8306308 | G9: =SUM(G4:G8) -> 12103000
B10: Operating lease vehicles, net | C10: 1791403 | D10: 3134080 | E10: 4116604 | F10: 2089758 | G10: 2447000
B11: Solar energy systems, leased and to be leased, net | C11: 0 | D11: 5919880 | E11: 6347490 | F11: 6271396 | G11: 6138000
B12: Property, plant and equipment, net | C12: 3403334 | D12: 5982957 | E12: 10027522 | F12: 11330077 | G12: 10396000
B13: Operating lease right-of-use assets | C13: 0 | D13: 0 | E13: 0 | F13: 0 | G13: 1218000
B14: Intangible assets, net | C14: 12816 | D14: 376145 | E14: 361502 | F14: 282492 | G14: 339000
B15: portion | C15: 0 | D15: 506302 | E15: =456652+60237 -> 516889 | F15: 489707 | G15: 591000
B16: Restricted cash, net of current portion | C16: 31522 | D16: 268165 | E16: 441722 | F16: 398219 | G16: 269000
B17: Other assets | C17: 46858 | D17: 216751 | E17: 273123 | F17: 571657 | G17: 808000
B18: Total assets | C18: =SUM(C9:C17) -> 8067939 | D18: =SUM(D9:D17) -> 22664076 | E18: =SUM(E9:E17) -> 28655372 | F18: =SUM(F9:F17) -> 29739614 | G18: =SUM(G9:G17) -> 34309000
B19: Accounts payable | C19: 916148 | D19: 1860341 | E19: 2390250 | F19: 3404451 | G19: 3771000
B20: Accrued liabilities | C20: 422798 | D20: 1210028 | E20: 1731366 | F20: 2094253 | G20: 2905000
B21: Deferred revenue | C21: 423961 | D21: 763126 | E21: 1015253 | F21: 630292 | G21: 1163000
B22: Resale value guarantees | C22: 136831 | D22: 179504 | E22: 787333 | F22: 502840 | G22: 317000
B23: Customer deposits | C23: 283370 | D23: 663859 | E23: 853919 | F23: 792601 | G23: 726000
B24: Current portion of long-term debt and capital leases | C24: 627927 | D24: 984211 | E24: 796549 | F24: 2567699 | G24: 1785000
B25: Current portion of solar bonds issued to related
B26: parties | C26: 0 | D26: 165936 | E26: 100000 | F26: 0 | G26: 0
B27: Total current liabilities | C27: 2811035 | D27: 5827005 | E27: =SUM(E19:E26) -> 7674670 | F27: =SUM(F19:F26) -> 9992136 | G27: =SUM(G19:G26) -> 10667000
B28: Long-term debt and capital leases, net of current
B29: portion | C29: 2021093 | D29: 5860049 | E29: 9415700 | F29: 9403672 | G29: 11634000
B30: Other liabilities | C30: 2152107 | D30: 5438936 | E30: 6330414 | F30: 4586166 | G30: 4541000
B31: Total liabilities | C31: =SUM(C27:C30) -> 6984235 | D31: =SUM(D27:D30) -> 17125990 | E31: =SUM(E27:E30) -> 23420784 | F31: =SUM(F27:F30) -> 23981974 | G31: =SUM(G27:G30) -> 26842000
B32: Total stockholders' equity | C32: 1083704 | D32: 4752911 | E32: 4237242 | F32: 4923243 | G32: 6618000
B33: Noncontrolling interests in subsidiaries | C33: 0 | D33: 785175 | E33: 997346 | F33: 834397 | G33: 849000
B34: Total liabilities and equity | C34: =C31+C32+C33 -> 8067939 | D34: =D31+D32+D33 -> 22664076 | E34: =E31+E32+E33 -> 28655372 | F34: =F31+F32+F33 -> 29739614 | G34: =G31+G32+G33 -> 34309000
B36: KPIs
B37: Liquidity ratios
B38: Quick ratio | C38: =(C4+C5)/C27 -> 0.43383878 | D38: =(D4+D5)/D27 -> 0.60043453 | E38: =(E4+E5)/E27 -> 0.45907342 | F38: =(F4+F5)/F27 -> 0.38812212 | G38: =(G4+G5)/G27 -> 0.61066842
B39: Current ratio | C39: =C9/C27 -> 0.9896732 | D39: =D9/D27 -> 1.0742733 | E39: =E9/E27 -> 0.85613062 | F39: =F9/F27 -> 0.83128452 | G39: =G9/G27 -> 1.1346208
B40: DSO | C40: =C6/'P&L Input'!C7*360 -> 15.033867 | D40: =D6/'P&L Input'!D7*360 -> 25.669676 | E40: =E6/'P&L Input'!E7*360 -> 15.778645 | F40: =F6/'P&L Input'!F7*360 -> 15.919279 | G40: =G6/'P&L Input'!G7*360 -> 19.392953
B41: DIO | C41: =-C7/SUM('P&L Input'!C8:C10)*360 -> 147.32376 | D41: =-D7/SUM('P&L Input'!D8:D10)*360 -> 137.80794 | E41: =-E7/SUM('P&L Input'!E8:E10)*360 -> 85.449954 | F41: =-F7/SUM('P&L Input'!F8:F10)*360 -> 64.344949 | G41: =-G7/SUM('P&L Input'!G8:G10)*360 -> 62.349213
B42: DPO | C42: =-C19/SUM('P&L Input'!C8:C10)*360 -> 105.62401 | D42: =-D19/SUM('P&L Input'!D8:D10)*360 -> 124.00264 | E42: =-E19/SUM('P&L Input'!E8:E10)*360 -> 90.23345 | F42: =-F19/SUM('P&L Input'!F8:F10)*360 -> 70.35909 | G42: =-G19/SUM('P&L Input'!G8:G10)*360 -> 66.193379
...

Sheet Workings -->
B14: Workings -->

Sheet Income Statement items
B14: Income Statement items

Sheet Automotive
B14: Automotive

Sheet Deliveries
B1: Deliveries
C3: Tesla Deliveries
B4: Vehicle | C4: 2015 Act | D4: 2016 Act | E4: 2017 Act | F4: 2018 Act | G4: 2019 Act | H4: 2020 Fcst | I4: 2021 Fcst | J4: 2022 Fcst | K4: 2023 Fcst | L4: 2024 Fcst | M4: 2025 Fcst | N4: 2026 Fcst | O4: 2027 Fcst | P4: 2028 Fcst | Q4: 2029 Fcst
B5: Tesla Model 3 | C5: 0 | D5: 0 | E5: 1764 | F5: 146055 | G5: 300815 | H5: =G5*(1+H15) -> 481304 | I5: =H5*(1+I15) -> 529434.4 | J5: =I5*(1+J15) -> 582377.84 | K5: =J5*(1+K15) -> 628968.07 | L5: =K5*(1+L15) -> 679285.51 | M5: =L5*(1+M15) -> 706456.93 | N5: =M5*(1+N15) -> 734715.21 | O5: =N5*(1+O15) -> 764103.82 | ... Q5: =P5*(1+Q15) -> 826454.69
B6: Tesla Model S and X | C6: 50580 | D6: 76230 | E6: 101312 | F6: 98865 | G6: 66385 | H6: =G6*(1+H16) -> 69040.4 | I6: =H6*(1+I16) -> 71802.016 | J6: =I6*(1+J16) -> 74674.097 | K6: =J6*(1+K16) -> 77661.061 | L6: =K6*(1+L16) -> 80767.503 | M6: =L6*(1+M16) -> 83998.203 | N6: =M6*(1+N16) -> 87358.131 | O6: =N6*(1+O16) -> 90852.456 | ... Q6: =P6*(1+Q16) -> 98266.017
B7: Tesla Model Y | C7: 0 | D7: 0 | E7: 0 | F7: 0 | G7: 0 | H7: =E5 -> 1764 | I7: =H7*(1+I17) -> 146055 | J7: =I7*(1+J17) -> 300815 | K7: =J7*(1+K17) -> 481304 | L7: =K7*(1+L17) -> 529434.4 | M7: =L7*(1+M17) -> 582377.84 | N7: =M7*(1+N17) -> 628968.07 | O7: =N7*(1+O17) -> 679285.51 | P7: =O7*(1+P17) -> 706456.93 | Q7: =P7*(1+Q17) -> 734715.21
B8: Tesla Roadster 2 | C8: 0 | D8: 0 | E8: 0 | F8: 0 | G8: 0 | H8: 0 | I8: 0 | J8: 500 | K8: =J8*(1+K18) -> 1000 | L8: =K8*(1+L18) -> 1500 | M8: =L8*(1+M18) -> 1650 | N8: =M8*(1+N18) -> 1815 | O8: =N8*(1+O18) -> 1960.2 | P8: =O8*(1+P18) -> 2117.016 | Q8: =P8*(1+Q18) -> 2201.6966
B9: Tesla Pickup | C9: 0 | D9: 0 | E9: 0 | F9: 0 | G9: 0 | H9: 0 | I9: 250 | J9: =I9*(1+J19) -> 20699.405 | K9: =J9*(1+K19) -> 42632.511 | L9: =K9*(1+L19) -> 68212.018 | M9: =L9*(1+M19) -> 75033.22 | N9: =M9*(1+N19) -> 82536.542 | O9: =N9*(1+O19) -> 89139.465 | P9: =O9*(1+P19) -> 96270.623 | Q9: =P9*(1+Q19) -> 100121.45
B10: Tesla Semi | C10: 0 | D10: 0 | E10: 0 | F10: 0 | G10: 0 | H10: 0 | I10: 250 | J10: =I10*(1+J20) -> 20699.405 | K10: =J10*(1+K20) -> 42632.511 | L10: =K10*(1+L20) -> 68212.018 | M10: =L10*(1+M20) -> 75033.22 | N10: =M10*(1+N20) -> 82536.542 | O10: =N10*(1+O20) -> 89139.465 | P10: =O10*(1+P20) -> 96270.623 | Q10: =P10*(1+Q20) -> 100121.45
B11: Total | C11: =SUM(C5:C10) -> 50580 | D11: =SUM(D5:D10) -> 76230 | E11: =SUM(E5:E10) -> 103076 | F11: =SUM(F5:F10) -> 244920 | G11: =SUM(G5:G10) -> 367200 | H11: =SUM(H5:H10) -> 552108.4 | I11: =SUM(I5:I10) -> 747791.42 | J11: =SUM(J5:J10) -> 999765.75 | ... Q11: =SUM(Q5:Q10) -> 1861880.5
B13: y-o-y growth %
B15: Tesla Model 3 | C15: n.a. | D15: n.a. | E15: n.a. | F15: =F5/E5-1 -> 81.797619 | G15: =G5/F5-1 -> 1.0596008 | H15: 0.6 | I15: =$C$25 -> 0.1 | J15: =$C$25 -> 0.1 | K15: =$C$26 -> 0.08 | L15: =$C$26 -> 0.08 | M15: =$C$27 -> 0.04 | N15: =$C$27 -> 0.04 | O15: =$C$27 -> 0.04 | P15: =$C$27 -> 0.04 | Q15: =$C$27 -> 0.04
B16: Tesla Model S and X | C16: n.a. | D16: =D6/C6-1 -> 0.50711744 | E16: =E6/D6-1 -> 0.32903057 | F16: =F6/E6-1 -> -0.024153111 | G16: =G6/F6-1 -> -0.3285288 | H16: =$C$27 -> 0.04 | I16: =$C$27 -> 0.04 | J16: =$C$27 -> 0.04 | K16: =$C$27 -> 0.04 | L16: =$C$27 -> 0.04 | M16: =$C$27 -> 0.04 | N16: =$C$27 -> 0.04 | O16: =$C$27 -> 0.04 | ... Q16: =$C$27 -> 0.04
B17: Tesla Model Y | C17: n.a. | D17: n.a. | E17: n.a. | F17: n.a. | G17: n.a. | H17: n.a. | I17: =F15 -> 81.797619 | J17: =G15 -> 1.0596008 | K17: =H15 -> 0.6 | L17: =I15 -> 0.1 | M17: =J15 -> 0.1 | N17: =K15 -> 0.08 | O17: =L15 -> 0.08 | P17: =M15 -> 0.04 | Q17: =N15 -> 0.04
B18: Tesla Roadster 2 | C18: n.a. | D18: n.a. | E18: n.a. | F18: n.a. | G18: n.a. | H18: n.a. | I18: n.a. | J18: n.a. | K18: 1 | L18: 0.5 | M18: =$C$25 -> 0.1 | N18: =$C$25 -> 0.1 | O18: =$C$26 -> 0.08 | P18: =$C$26 -> 0.08 | Q18: =$C$27 -> 0.04
B19: Tesla Pickup | C19: n.a. | D19: n.a. | E19: n.a. | F19: n.a. | G19: n.a. | H19: n.a. | I19: n.a. | J19: =F$15 -> 81.797619 | K19: =G$15 -> 1.0596008 | L19: =H$15 -> 0.6 | M19: =$C$25 -> 0.1 | N19: =$C$25 -> 0.1 | O19: =$C$26 -> 0.08 | P19: =$C$26 -> 0.08 | Q19: =$C$27 -> 0.04
B20: Tesla Semi | C20: n.a. | D20: n.a. | E20: n.a. | F20: n.a. | G20: n.a. | H20: n.a. | I20: n.a. | J20: =F$15 -> 81.797619 | K20: =G$15 -> 1.0596008 | L20: =H$15 -> 0.6 | M20: =$C$25 -> 0.1 | N20: =$C$25 -> 0.1 | O20: =$C$26 -> 0.08 | P20: =$C$26 -> 0.08 | Q20: =$C$27 -> 0.04
B24: Assumed growth after introduction:
B25: 2 years | C25: 0.1
B26: 2 years | C26: 0.08
B27: onwards | C27: 0.04

Sheet Deliveries development

Sheet Deliveries comparables
B1: Deliveries comparables
B3: Comparables 2015-2019
B6: Vehicle Sales 2015-2019 - average | C6: Average | D6: Adj. Average
B7: GM | C7: 9600340 | D7: =C7 -> 9600340
B8: Ford | C8: 6607000 | D8: =C8 -> 6607000
B9: Fiat Chrysler | C9: 4740000 | D9: =C9 -> 4740000
B10: BMW | C10: 2460000 | D10: =C10 -> 2460000
B11: Volkswagen | C11: 10700000 | D11: =C11 -> 10700000
B12: Jaguar | C12: n.a. | D12: n.a.
B13: Porsche | C13: n.a. | D13: n.a.
B14: Ferrari | C14: n.a. | D14: n.a.
B15: Scania | C15: n.a. | D15: n.a.
B16: MAN | C16: n.a. | D16: n.a.
B17: Paccar | C17: n.a. | D17: n.a.
B18: Average | C18: n.a. | D18: =AVERAGE(D7:D17) -> 6821468
B22: Tesla Expected Deliveries
B23: 2020 | D23: =Deliveries!H$11 -> 552108.4
B24: 2024 | D24: =Deliveries!L$11 -> 1427411.5
B25: 2029 | D25: =Deliveries!Q$11 -> 1861880.5
